{
 "cells": [
  {
   "cell_type": "code",
   "execution_count": null,
   "metadata": {},
   "outputs": [],
   "source": [
    "# We will run spark from Python it is called PySpark\n",
    "# conda install -c conda-forge pyspark\n",
    "# pip install pyspark\n",
    "# export PATH=\"home/hadoopuser/anaconda3/envs/python3/bin:$PATH\"\n"
   ]
  },
  {
   "cell_type": "code",
   "execution_count": 1,
   "metadata": {},
   "outputs": [
    {
     "name": "stdout",
     "output_type": "stream",
     "text": [
      "2.4\n"
     ]
    }
   ],
   "source": [
    "\n",
    "from pyspark import SparkContext\n",
    "sc =SparkContext()\n",
    "\n",
    "\n",
    "import random\n",
    "num_samples = 10\n",
    "\n",
    "def inside(p):     \n",
    "  x, y = random.random(), random.random()\n",
    "  return x*x + y*y < 1\n",
    "\n",
    "count = sc.parallelize(range(0, num_samples)).filter(inside).count()\n",
    "\n",
    "pi = 4 * count / num_samples\n",
    "print(pi)\n",
    "\n",
    "sc.stop()"
   ]
  },
  {
   "cell_type": "code",
   "execution_count": 8,
   "metadata": {},
   "outputs": [],
   "source": [
    "sc.stop()"
   ]
  },
  {
   "cell_type": "code",
   "execution_count": 9,
   "metadata": {},
   "outputs": [],
   "source": [
    "from pyspark import SparkContext\n",
    "sc =SparkContext()\n",
    "\n",
    "text_file = sc.textFile(\"file:///home/hadoopuser/input.txt\")\n",
    "counts = text_file.flatMap(lambda line: line.split(\" \")) \\\n",
    "             .map(lambda word: (word, 1)) \\\n",
    "             .reduceByKey(lambda a, b: a + b)\n",
    "counts.saveAsTextFile(\"file:///home/joshi/output2\")\n",
    "sc.stop()\n",
    "\n",
    "#fight is with the user permission\n"
   ]
  },
  {
   "cell_type": "code",
   "execution_count": 25,
   "metadata": {},
   "outputs": [],
   "source": [
    "sc.stop()"
   ]
  },
  {
   "cell_type": "code",
   "execution_count": 8,
   "metadata": {},
   "outputs": [
    {
     "ename": "AttributeError",
     "evalue": "'PipelinedRDD' object has no attribute 'toDF'",
     "output_type": "error",
     "traceback": [
      "\u001b[0;31m---------------------------------------------------------------------------\u001b[0m",
      "\u001b[0;31mAttributeError\u001b[0m                            Traceback (most recent call last)",
      "\u001b[0;32m<ipython-input-8-9c163c4156b3>\u001b[0m in \u001b[0;36m<module>\u001b[0;34m()\u001b[0m\n\u001b[1;32m     11\u001b[0m \u001b[0;34m\u001b[0m\u001b[0m\n\u001b[1;32m     12\u001b[0m \u001b[0;31m# Creates a DataFrame having a single column named \"line\"\u001b[0m\u001b[0;34m\u001b[0m\u001b[0;34m\u001b[0m\u001b[0m\n\u001b[0;32m---> 13\u001b[0;31m \u001b[0mdf\u001b[0m \u001b[0;34m=\u001b[0m \u001b[0mnewRDD\u001b[0m\u001b[0;34m.\u001b[0m\u001b[0mmap\u001b[0m\u001b[0;34m(\u001b[0m\u001b[0;32mlambda\u001b[0m \u001b[0mr\u001b[0m\u001b[0;34m:\u001b[0m \u001b[0mRow\u001b[0m\u001b[0;34m(\u001b[0m\u001b[0mr\u001b[0m\u001b[0;34m)\u001b[0m\u001b[0;34m)\u001b[0m\u001b[0;34m.\u001b[0m\u001b[0mtoDF\u001b[0m\u001b[0;34m(\u001b[0m\u001b[0;34m[\u001b[0m\u001b[0;34m\"line\"\u001b[0m\u001b[0;34m]\u001b[0m\u001b[0;34m)\u001b[0m\u001b[0;34m\u001b[0m\u001b[0m\n\u001b[0m\u001b[1;32m     14\u001b[0m \u001b[0;34m\u001b[0m\u001b[0m\n\u001b[1;32m     15\u001b[0m \u001b[0;31m#df = textFile.map(lambda r: Row(r)).toDF([\"line\"])\u001b[0m\u001b[0;34m\u001b[0m\u001b[0;34m\u001b[0m\u001b[0m\n",
      "\u001b[0;31mAttributeError\u001b[0m: 'PipelinedRDD' object has no attribute 'toDF'"
     ]
    }
   ],
   "source": [
    "sc.stop()\n",
    "from pyspark import SparkContext\n",
    "sc =SparkContext()\n",
    "\n",
    "\n",
    "\n",
    "textFile = sc.textFile(\"file:///home/j/input.txt\")\n",
    "#textFile.toDF().show()\n",
    "#\n",
    "newRDD = textFile.map(...)\n",
    "\n",
    "# Creates a DataFrame having a single column named \"line\"\n",
    "df = newRDD.map(lambda r: Row(r)).toDF([\"line\"])\n",
    "\n",
    "#df = textFile.map(lambda r: Row(r)).toDF([\"line\"])\n",
    "#errors = df.filter(col(\"line\").like(\"%ERROR%\"))\n",
    "# Counts all the errors\n",
    "#errors.count()\n",
    "# Counts errors mentioning MySQL\n",
    "#errors.filter(col(\"line\").like(\"%MySQL%\")).count()\n",
    "# Fetches the MySQL errors as an array of strings\n",
    "#errors.filter(col(\"line\").like(\"%MySQL%\")).collect()"
   ]
  },
  {
   "cell_type": "code",
   "execution_count": 11,
   "metadata": {},
   "outputs": [
    {
     "name": "stdout",
     "output_type": "stream",
     "text": [
      "+---+---+\n",
      "| _1| _2|\n",
      "+---+---+\n",
      "|  a|  1|\n",
      "+---+---+\n",
      "\n"
     ]
    }
   ],
   "source": [
    "\n",
    "sc.stop()\n",
    "\n",
    "from pyspark.sql import SparkSession\n",
    "from pyspark import SparkContext\n",
    "\n",
    "sc = SparkContext()\n",
    "\n",
    "rdd = sc.parallelize([(\"a\", 1)])\n",
    "hasattr(rdd, \"toDF\")\n",
    "## False\n",
    "\n",
    "spark = SparkSession(sc)\n",
    "hasattr(rdd, \"toDF\")\n",
    "## True\n",
    "\n",
    "rdd.toDF().show()"
   ]
  },
  {
   "cell_type": "code",
   "execution_count": 13,
   "metadata": {},
   "outputs": [
    {
     "ename": "Py4JJavaError",
     "evalue": "An error occurred while calling z:org.apache.spark.api.python.PythonRDD.runJob.\n: org.apache.spark.SparkException: Job aborted due to stage failure: Task 0 in stage 0.0 failed 1 times, most recent failure: Lost task 0.0 in stage 0.0 (TID 0, localhost, executor driver): org.apache.spark.api.python.PythonException: Traceback (most recent call last):\n  File \"/home/hadoopuser/anaconda3/lib/python3.6/site-packages/pyspark/python/lib/pyspark.zip/pyspark/worker.py\", line 230, in main\n    process()\n  File \"/home/hadoopuser/anaconda3/lib/python3.6/site-packages/pyspark/python/lib/pyspark.zip/pyspark/worker.py\", line 225, in process\n    serializer.dump_stream(func(split_index, iterator), outfile)\n  File \"/home/hadoopuser/anaconda3/lib/python3.6/site-packages/pyspark/python/lib/pyspark.zip/pyspark/serializers.py\", line 372, in dump_stream\n    vs = list(itertools.islice(iterator, batch))\n  File \"/home/hadoopuser/anaconda3/lib/python3.6/site-packages/pyspark/rdd.py\", line 1371, in takeUpToNumLeft\n    yield next(iterator)\n  File \"/home/hadoopuser/anaconda3/lib/python3.6/site-packages/pyspark/python/lib/pyspark.zip/pyspark/util.py\", line 55, in wrapper\n    return f(*args, **kwargs)\n  File \"<ipython-input-13-bd24de00a52c>\", line 11, in <lambda>\nNameError: name 'Row' is not defined\n\n\tat org.apache.spark.api.python.BasePythonRunner$ReaderIterator.handlePythonException(PythonRunner.scala:298)\n\tat org.apache.spark.api.python.PythonRunner$$anon$1.read(PythonRunner.scala:438)\n\tat org.apache.spark.api.python.PythonRunner$$anon$1.read(PythonRunner.scala:421)\n\tat org.apache.spark.api.python.BasePythonRunner$ReaderIterator.hasNext(PythonRunner.scala:252)\n\tat org.apache.spark.InterruptibleIterator.hasNext(InterruptibleIterator.scala:37)\n\tat scala.collection.Iterator$class.foreach(Iterator.scala:893)\n\tat org.apache.spark.InterruptibleIterator.foreach(InterruptibleIterator.scala:28)\n\tat scala.collection.generic.Growable$class.$plus$plus$eq(Growable.scala:59)\n\tat scala.collection.mutable.ArrayBuffer.$plus$plus$eq(ArrayBuffer.scala:104)\n\tat scala.collection.mutable.ArrayBuffer.$plus$plus$eq(ArrayBuffer.scala:48)\n\tat scala.collection.TraversableOnce$class.to(TraversableOnce.scala:310)\n\tat org.apache.spark.InterruptibleIterator.to(InterruptibleIterator.scala:28)\n\tat scala.collection.TraversableOnce$class.toBuffer(TraversableOnce.scala:302)\n\tat org.apache.spark.InterruptibleIterator.toBuffer(InterruptibleIterator.scala:28)\n\tat scala.collection.TraversableOnce$class.toArray(TraversableOnce.scala:289)\n\tat org.apache.spark.InterruptibleIterator.toArray(InterruptibleIterator.scala:28)\n\tat org.apache.spark.api.python.PythonRDD$$anonfun$3.apply(PythonRDD.scala:149)\n\tat org.apache.spark.api.python.PythonRDD$$anonfun$3.apply(PythonRDD.scala:149)\n\tat org.apache.spark.SparkContext$$anonfun$runJob$5.apply(SparkContext.scala:2074)\n\tat org.apache.spark.SparkContext$$anonfun$runJob$5.apply(SparkContext.scala:2074)\n\tat org.apache.spark.scheduler.ResultTask.runTask(ResultTask.scala:87)\n\tat org.apache.spark.scheduler.Task.run(Task.scala:109)\n\tat org.apache.spark.executor.Executor$TaskRunner.run(Executor.scala:345)\n\tat java.util.concurrent.ThreadPoolExecutor.runWorker(ThreadPoolExecutor.java:1149)\n\tat java.util.concurrent.ThreadPoolExecutor$Worker.run(ThreadPoolExecutor.java:624)\n\tat java.lang.Thread.run(Thread.java:748)\n\nDriver stacktrace:\n\tat org.apache.spark.scheduler.DAGScheduler.org$apache$spark$scheduler$DAGScheduler$$failJobAndIndependentStages(DAGScheduler.scala:1602)\n\tat org.apache.spark.scheduler.DAGScheduler$$anonfun$abortStage$1.apply(DAGScheduler.scala:1590)\n\tat org.apache.spark.scheduler.DAGScheduler$$anonfun$abortStage$1.apply(DAGScheduler.scala:1589)\n\tat scala.collection.mutable.ResizableArray$class.foreach(ResizableArray.scala:59)\n\tat scala.collection.mutable.ArrayBuffer.foreach(ArrayBuffer.scala:48)\n\tat org.apache.spark.scheduler.DAGScheduler.abortStage(DAGScheduler.scala:1589)\n\tat org.apache.spark.scheduler.DAGScheduler$$anonfun$handleTaskSetFailed$1.apply(DAGScheduler.scala:831)\n\tat org.apache.spark.scheduler.DAGScheduler$$anonfun$handleTaskSetFailed$1.apply(DAGScheduler.scala:831)\n\tat scala.Option.foreach(Option.scala:257)\n\tat org.apache.spark.scheduler.DAGScheduler.handleTaskSetFailed(DAGScheduler.scala:831)\n\tat org.apache.spark.scheduler.DAGSchedulerEventProcessLoop.doOnReceive(DAGScheduler.scala:1823)\n\tat org.apache.spark.scheduler.DAGSchedulerEventProcessLoop.onReceive(DAGScheduler.scala:1772)\n\tat org.apache.spark.scheduler.DAGSchedulerEventProcessLoop.onReceive(DAGScheduler.scala:1761)\n\tat org.apache.spark.util.EventLoop$$anon$1.run(EventLoop.scala:48)\n\tat org.apache.spark.scheduler.DAGScheduler.runJob(DAGScheduler.scala:642)\n\tat org.apache.spark.SparkContext.runJob(SparkContext.scala:2034)\n\tat org.apache.spark.SparkContext.runJob(SparkContext.scala:2055)\n\tat org.apache.spark.SparkContext.runJob(SparkContext.scala:2074)\n\tat org.apache.spark.api.python.PythonRDD$.runJob(PythonRDD.scala:149)\n\tat org.apache.spark.api.python.PythonRDD.runJob(PythonRDD.scala)\n\tat sun.reflect.NativeMethodAccessorImpl.invoke0(Native Method)\n\tat sun.reflect.NativeMethodAccessorImpl.invoke(NativeMethodAccessorImpl.java:62)\n\tat sun.reflect.DelegatingMethodAccessorImpl.invoke(DelegatingMethodAccessorImpl.java:43)\n\tat java.lang.reflect.Method.invoke(Method.java:498)\n\tat py4j.reflection.MethodInvoker.invoke(MethodInvoker.java:244)\n\tat py4j.reflection.ReflectionEngine.invoke(ReflectionEngine.java:357)\n\tat py4j.Gateway.invoke(Gateway.java:282)\n\tat py4j.commands.AbstractCommand.invokeMethod(AbstractCommand.java:132)\n\tat py4j.commands.CallCommand.execute(CallCommand.java:79)\n\tat py4j.GatewayConnection.run(GatewayConnection.java:238)\n\tat java.lang.Thread.run(Thread.java:748)\nCaused by: org.apache.spark.api.python.PythonException: Traceback (most recent call last):\n  File \"/home/hadoopuser/anaconda3/lib/python3.6/site-packages/pyspark/python/lib/pyspark.zip/pyspark/worker.py\", line 230, in main\n    process()\n  File \"/home/hadoopuser/anaconda3/lib/python3.6/site-packages/pyspark/python/lib/pyspark.zip/pyspark/worker.py\", line 225, in process\n    serializer.dump_stream(func(split_index, iterator), outfile)\n  File \"/home/hadoopuser/anaconda3/lib/python3.6/site-packages/pyspark/python/lib/pyspark.zip/pyspark/serializers.py\", line 372, in dump_stream\n    vs = list(itertools.islice(iterator, batch))\n  File \"/home/hadoopuser/anaconda3/lib/python3.6/site-packages/pyspark/rdd.py\", line 1371, in takeUpToNumLeft\n    yield next(iterator)\n  File \"/home/hadoopuser/anaconda3/lib/python3.6/site-packages/pyspark/python/lib/pyspark.zip/pyspark/util.py\", line 55, in wrapper\n    return f(*args, **kwargs)\n  File \"<ipython-input-13-bd24de00a52c>\", line 11, in <lambda>\nNameError: name 'Row' is not defined\n\n\tat org.apache.spark.api.python.BasePythonRunner$ReaderIterator.handlePythonException(PythonRunner.scala:298)\n\tat org.apache.spark.api.python.PythonRunner$$anon$1.read(PythonRunner.scala:438)\n\tat org.apache.spark.api.python.PythonRunner$$anon$1.read(PythonRunner.scala:421)\n\tat org.apache.spark.api.python.BasePythonRunner$ReaderIterator.hasNext(PythonRunner.scala:252)\n\tat org.apache.spark.InterruptibleIterator.hasNext(InterruptibleIterator.scala:37)\n\tat scala.collection.Iterator$class.foreach(Iterator.scala:893)\n\tat org.apache.spark.InterruptibleIterator.foreach(InterruptibleIterator.scala:28)\n\tat scala.collection.generic.Growable$class.$plus$plus$eq(Growable.scala:59)\n\tat scala.collection.mutable.ArrayBuffer.$plus$plus$eq(ArrayBuffer.scala:104)\n\tat scala.collection.mutable.ArrayBuffer.$plus$plus$eq(ArrayBuffer.scala:48)\n\tat scala.collection.TraversableOnce$class.to(TraversableOnce.scala:310)\n\tat org.apache.spark.InterruptibleIterator.to(InterruptibleIterator.scala:28)\n\tat scala.collection.TraversableOnce$class.toBuffer(TraversableOnce.scala:302)\n\tat org.apache.spark.InterruptibleIterator.toBuffer(InterruptibleIterator.scala:28)\n\tat scala.collection.TraversableOnce$class.toArray(TraversableOnce.scala:289)\n\tat org.apache.spark.InterruptibleIterator.toArray(InterruptibleIterator.scala:28)\n\tat org.apache.spark.api.python.PythonRDD$$anonfun$3.apply(PythonRDD.scala:149)\n\tat org.apache.spark.api.python.PythonRDD$$anonfun$3.apply(PythonRDD.scala:149)\n\tat org.apache.spark.SparkContext$$anonfun$runJob$5.apply(SparkContext.scala:2074)\n\tat org.apache.spark.SparkContext$$anonfun$runJob$5.apply(SparkContext.scala:2074)\n\tat org.apache.spark.scheduler.ResultTask.runTask(ResultTask.scala:87)\n\tat org.apache.spark.scheduler.Task.run(Task.scala:109)\n\tat org.apache.spark.executor.Executor$TaskRunner.run(Executor.scala:345)\n\tat java.util.concurrent.ThreadPoolExecutor.runWorker(ThreadPoolExecutor.java:1149)\n\tat java.util.concurrent.ThreadPoolExecutor$Worker.run(ThreadPoolExecutor.java:624)\n\t... 1 more\n",
     "output_type": "error",
     "traceback": [
      "\u001b[0;31m---------------------------------------------------------------------------\u001b[0m",
      "\u001b[0;31mPy4JJavaError\u001b[0m                             Traceback (most recent call last)",
      "\u001b[0;32m<ipython-input-13-bd24de00a52c>\u001b[0m in \u001b[0;36m<module>\u001b[0;34m()\u001b[0m\n\u001b[1;32m      9\u001b[0m \u001b[0;34m\u001b[0m\u001b[0m\n\u001b[1;32m     10\u001b[0m \u001b[0;31m# Creates a DataFrame having a single column named \"line\"\u001b[0m\u001b[0;34m\u001b[0m\u001b[0;34m\u001b[0m\u001b[0m\n\u001b[0;32m---> 11\u001b[0;31m \u001b[0mdf\u001b[0m \u001b[0;34m=\u001b[0m \u001b[0mtextFile\u001b[0m\u001b[0;34m.\u001b[0m\u001b[0mmap\u001b[0m\u001b[0;34m(\u001b[0m\u001b[0;32mlambda\u001b[0m \u001b[0mr\u001b[0m\u001b[0;34m:\u001b[0m \u001b[0mRow\u001b[0m\u001b[0;34m(\u001b[0m\u001b[0mr\u001b[0m\u001b[0;34m)\u001b[0m\u001b[0;34m)\u001b[0m\u001b[0;34m.\u001b[0m\u001b[0mtoDF\u001b[0m\u001b[0;34m(\u001b[0m\u001b[0;34m[\u001b[0m\u001b[0;34m\"line\"\u001b[0m\u001b[0;34m]\u001b[0m\u001b[0;34m)\u001b[0m\u001b[0;34m\u001b[0m\u001b[0m\n\u001b[0m\u001b[1;32m     12\u001b[0m \u001b[0merrors\u001b[0m \u001b[0;34m=\u001b[0m \u001b[0mdf\u001b[0m\u001b[0;34m.\u001b[0m\u001b[0mfilter\u001b[0m\u001b[0;34m(\u001b[0m\u001b[0mcol\u001b[0m\u001b[0;34m(\u001b[0m\u001b[0;34m\"line\"\u001b[0m\u001b[0;34m)\u001b[0m\u001b[0;34m.\u001b[0m\u001b[0mlike\u001b[0m\u001b[0;34m(\u001b[0m\u001b[0;34m\"%ERROR%\"\u001b[0m\u001b[0;34m)\u001b[0m\u001b[0;34m)\u001b[0m\u001b[0;34m\u001b[0m\u001b[0m\n\u001b[1;32m     13\u001b[0m \u001b[0;31m# Counts all the errors\u001b[0m\u001b[0;34m\u001b[0m\u001b[0;34m\u001b[0m\u001b[0m\n",
      "\u001b[0;32m/home/hadoopuser/anaconda3/lib/python3.6/site-packages/pyspark/sql/session.py\u001b[0m in \u001b[0;36mtoDF\u001b[0;34m(self, schema, sampleRatio)\u001b[0m\n\u001b[1;32m     56\u001b[0m         \u001b[0;34m[\u001b[0m\u001b[0mRow\u001b[0m\u001b[0;34m(\u001b[0m\u001b[0mname\u001b[0m\u001b[0;34m=\u001b[0m\u001b[0;34mu'Alice'\u001b[0m\u001b[0;34m,\u001b[0m \u001b[0mage\u001b[0m\u001b[0;34m=\u001b[0m\u001b[0;36m1\u001b[0m\u001b[0;34m)\u001b[0m\u001b[0;34m]\u001b[0m\u001b[0;34m\u001b[0m\u001b[0m\n\u001b[1;32m     57\u001b[0m         \"\"\"\n\u001b[0;32m---> 58\u001b[0;31m         \u001b[0;32mreturn\u001b[0m \u001b[0msparkSession\u001b[0m\u001b[0;34m.\u001b[0m\u001b[0mcreateDataFrame\u001b[0m\u001b[0;34m(\u001b[0m\u001b[0mself\u001b[0m\u001b[0;34m,\u001b[0m \u001b[0mschema\u001b[0m\u001b[0;34m,\u001b[0m \u001b[0msampleRatio\u001b[0m\u001b[0;34m)\u001b[0m\u001b[0;34m\u001b[0m\u001b[0m\n\u001b[0m\u001b[1;32m     59\u001b[0m \u001b[0;34m\u001b[0m\u001b[0m\n\u001b[1;32m     60\u001b[0m     \u001b[0mRDD\u001b[0m\u001b[0;34m.\u001b[0m\u001b[0mtoDF\u001b[0m \u001b[0;34m=\u001b[0m \u001b[0mtoDF\u001b[0m\u001b[0;34m\u001b[0m\u001b[0m\n",
      "\u001b[0;32m/home/hadoopuser/anaconda3/lib/python3.6/site-packages/pyspark/sql/session.py\u001b[0m in \u001b[0;36mcreateDataFrame\u001b[0;34m(self, data, schema, samplingRatio, verifySchema)\u001b[0m\n\u001b[1;32m    687\u001b[0m \u001b[0;34m\u001b[0m\u001b[0m\n\u001b[1;32m    688\u001b[0m         \u001b[0;32mif\u001b[0m \u001b[0misinstance\u001b[0m\u001b[0;34m(\u001b[0m\u001b[0mdata\u001b[0m\u001b[0;34m,\u001b[0m \u001b[0mRDD\u001b[0m\u001b[0;34m)\u001b[0m\u001b[0;34m:\u001b[0m\u001b[0;34m\u001b[0m\u001b[0m\n\u001b[0;32m--> 689\u001b[0;31m             \u001b[0mrdd\u001b[0m\u001b[0;34m,\u001b[0m \u001b[0mschema\u001b[0m \u001b[0;34m=\u001b[0m \u001b[0mself\u001b[0m\u001b[0;34m.\u001b[0m\u001b[0m_createFromRDD\u001b[0m\u001b[0;34m(\u001b[0m\u001b[0mdata\u001b[0m\u001b[0;34m.\u001b[0m\u001b[0mmap\u001b[0m\u001b[0;34m(\u001b[0m\u001b[0mprepare\u001b[0m\u001b[0;34m)\u001b[0m\u001b[0;34m,\u001b[0m \u001b[0mschema\u001b[0m\u001b[0;34m,\u001b[0m \u001b[0msamplingRatio\u001b[0m\u001b[0;34m)\u001b[0m\u001b[0;34m\u001b[0m\u001b[0m\n\u001b[0m\u001b[1;32m    690\u001b[0m         \u001b[0;32melse\u001b[0m\u001b[0;34m:\u001b[0m\u001b[0;34m\u001b[0m\u001b[0m\n\u001b[1;32m    691\u001b[0m             \u001b[0mrdd\u001b[0m\u001b[0;34m,\u001b[0m \u001b[0mschema\u001b[0m \u001b[0;34m=\u001b[0m \u001b[0mself\u001b[0m\u001b[0;34m.\u001b[0m\u001b[0m_createFromLocal\u001b[0m\u001b[0;34m(\u001b[0m\u001b[0mmap\u001b[0m\u001b[0;34m(\u001b[0m\u001b[0mprepare\u001b[0m\u001b[0;34m,\u001b[0m \u001b[0mdata\u001b[0m\u001b[0;34m)\u001b[0m\u001b[0;34m,\u001b[0m \u001b[0mschema\u001b[0m\u001b[0;34m)\u001b[0m\u001b[0;34m\u001b[0m\u001b[0m\n",
      "\u001b[0;32m/home/hadoopuser/anaconda3/lib/python3.6/site-packages/pyspark/sql/session.py\u001b[0m in \u001b[0;36m_createFromRDD\u001b[0;34m(self, rdd, schema, samplingRatio)\u001b[0m\n\u001b[1;32m    382\u001b[0m         \"\"\"\n\u001b[1;32m    383\u001b[0m         \u001b[0;32mif\u001b[0m \u001b[0mschema\u001b[0m \u001b[0;32mis\u001b[0m \u001b[0;32mNone\u001b[0m \u001b[0;32mor\u001b[0m \u001b[0misinstance\u001b[0m\u001b[0;34m(\u001b[0m\u001b[0mschema\u001b[0m\u001b[0;34m,\u001b[0m \u001b[0;34m(\u001b[0m\u001b[0mlist\u001b[0m\u001b[0;34m,\u001b[0m \u001b[0mtuple\u001b[0m\u001b[0;34m)\u001b[0m\u001b[0;34m)\u001b[0m\u001b[0;34m:\u001b[0m\u001b[0;34m\u001b[0m\u001b[0m\n\u001b[0;32m--> 384\u001b[0;31m             \u001b[0mstruct\u001b[0m \u001b[0;34m=\u001b[0m \u001b[0mself\u001b[0m\u001b[0;34m.\u001b[0m\u001b[0m_inferSchema\u001b[0m\u001b[0;34m(\u001b[0m\u001b[0mrdd\u001b[0m\u001b[0;34m,\u001b[0m \u001b[0msamplingRatio\u001b[0m\u001b[0;34m,\u001b[0m \u001b[0mnames\u001b[0m\u001b[0;34m=\u001b[0m\u001b[0mschema\u001b[0m\u001b[0;34m)\u001b[0m\u001b[0;34m\u001b[0m\u001b[0m\n\u001b[0m\u001b[1;32m    385\u001b[0m             \u001b[0mconverter\u001b[0m \u001b[0;34m=\u001b[0m \u001b[0m_create_converter\u001b[0m\u001b[0;34m(\u001b[0m\u001b[0mstruct\u001b[0m\u001b[0;34m)\u001b[0m\u001b[0;34m\u001b[0m\u001b[0m\n\u001b[1;32m    386\u001b[0m             \u001b[0mrdd\u001b[0m \u001b[0;34m=\u001b[0m \u001b[0mrdd\u001b[0m\u001b[0;34m.\u001b[0m\u001b[0mmap\u001b[0m\u001b[0;34m(\u001b[0m\u001b[0mconverter\u001b[0m\u001b[0;34m)\u001b[0m\u001b[0;34m\u001b[0m\u001b[0m\n",
      "\u001b[0;32m/home/hadoopuser/anaconda3/lib/python3.6/site-packages/pyspark/sql/session.py\u001b[0m in \u001b[0;36m_inferSchema\u001b[0;34m(self, rdd, samplingRatio, names)\u001b[0m\n\u001b[1;32m    353\u001b[0m         \u001b[0;34m:\u001b[0m\u001b[0;32mreturn\u001b[0m\u001b[0;34m:\u001b[0m \u001b[0;34m:\u001b[0m\u001b[0;32mclass\u001b[0m\u001b[0;34m:\u001b[0m\u001b[0;31m`\u001b[0m\u001b[0mpyspark\u001b[0m\u001b[0;34m.\u001b[0m\u001b[0msql\u001b[0m\u001b[0;34m.\u001b[0m\u001b[0mtypes\u001b[0m\u001b[0;34m.\u001b[0m\u001b[0mStructType\u001b[0m\u001b[0;31m`\u001b[0m\u001b[0;34m\u001b[0m\u001b[0m\n\u001b[1;32m    354\u001b[0m         \"\"\"\n\u001b[0;32m--> 355\u001b[0;31m         \u001b[0mfirst\u001b[0m \u001b[0;34m=\u001b[0m \u001b[0mrdd\u001b[0m\u001b[0;34m.\u001b[0m\u001b[0mfirst\u001b[0m\u001b[0;34m(\u001b[0m\u001b[0;34m)\u001b[0m\u001b[0;34m\u001b[0m\u001b[0m\n\u001b[0m\u001b[1;32m    356\u001b[0m         \u001b[0;32mif\u001b[0m \u001b[0;32mnot\u001b[0m \u001b[0mfirst\u001b[0m\u001b[0;34m:\u001b[0m\u001b[0;34m\u001b[0m\u001b[0m\n\u001b[1;32m    357\u001b[0m             raise ValueError(\"The first row in RDD is empty, \"\n",
      "\u001b[0;32m/home/hadoopuser/anaconda3/lib/python3.6/site-packages/pyspark/rdd.py\u001b[0m in \u001b[0;36mfirst\u001b[0;34m(self)\u001b[0m\n\u001b[1;32m   1391\u001b[0m         \u001b[0mValueError\u001b[0m\u001b[0;34m:\u001b[0m \u001b[0mRDD\u001b[0m \u001b[0;32mis\u001b[0m \u001b[0mempty\u001b[0m\u001b[0;34m\u001b[0m\u001b[0m\n\u001b[1;32m   1392\u001b[0m         \"\"\"\n\u001b[0;32m-> 1393\u001b[0;31m         \u001b[0mrs\u001b[0m \u001b[0;34m=\u001b[0m \u001b[0mself\u001b[0m\u001b[0;34m.\u001b[0m\u001b[0mtake\u001b[0m\u001b[0;34m(\u001b[0m\u001b[0;36m1\u001b[0m\u001b[0;34m)\u001b[0m\u001b[0;34m\u001b[0m\u001b[0m\n\u001b[0m\u001b[1;32m   1394\u001b[0m         \u001b[0;32mif\u001b[0m \u001b[0mrs\u001b[0m\u001b[0;34m:\u001b[0m\u001b[0;34m\u001b[0m\u001b[0m\n\u001b[1;32m   1395\u001b[0m             \u001b[0;32mreturn\u001b[0m \u001b[0mrs\u001b[0m\u001b[0;34m[\u001b[0m\u001b[0;36m0\u001b[0m\u001b[0;34m]\u001b[0m\u001b[0;34m\u001b[0m\u001b[0m\n",
      "\u001b[0;32m/home/hadoopuser/anaconda3/lib/python3.6/site-packages/pyspark/rdd.py\u001b[0m in \u001b[0;36mtake\u001b[0;34m(self, num)\u001b[0m\n\u001b[1;32m   1373\u001b[0m \u001b[0;34m\u001b[0m\u001b[0m\n\u001b[1;32m   1374\u001b[0m             \u001b[0mp\u001b[0m \u001b[0;34m=\u001b[0m \u001b[0mrange\u001b[0m\u001b[0;34m(\u001b[0m\u001b[0mpartsScanned\u001b[0m\u001b[0;34m,\u001b[0m \u001b[0mmin\u001b[0m\u001b[0;34m(\u001b[0m\u001b[0mpartsScanned\u001b[0m \u001b[0;34m+\u001b[0m \u001b[0mnumPartsToTry\u001b[0m\u001b[0;34m,\u001b[0m \u001b[0mtotalParts\u001b[0m\u001b[0;34m)\u001b[0m\u001b[0;34m)\u001b[0m\u001b[0;34m\u001b[0m\u001b[0m\n\u001b[0;32m-> 1375\u001b[0;31m             \u001b[0mres\u001b[0m \u001b[0;34m=\u001b[0m \u001b[0mself\u001b[0m\u001b[0;34m.\u001b[0m\u001b[0mcontext\u001b[0m\u001b[0;34m.\u001b[0m\u001b[0mrunJob\u001b[0m\u001b[0;34m(\u001b[0m\u001b[0mself\u001b[0m\u001b[0;34m,\u001b[0m \u001b[0mtakeUpToNumLeft\u001b[0m\u001b[0;34m,\u001b[0m \u001b[0mp\u001b[0m\u001b[0;34m)\u001b[0m\u001b[0;34m\u001b[0m\u001b[0m\n\u001b[0m\u001b[1;32m   1376\u001b[0m \u001b[0;34m\u001b[0m\u001b[0m\n\u001b[1;32m   1377\u001b[0m             \u001b[0mitems\u001b[0m \u001b[0;34m+=\u001b[0m \u001b[0mres\u001b[0m\u001b[0;34m\u001b[0m\u001b[0m\n",
      "\u001b[0;32m/home/hadoopuser/anaconda3/lib/python3.6/site-packages/pyspark/context.py\u001b[0m in \u001b[0;36mrunJob\u001b[0;34m(self, rdd, partitionFunc, partitions, allowLocal)\u001b[0m\n\u001b[1;32m   1011\u001b[0m         \u001b[0;31m# SparkContext#runJob.\u001b[0m\u001b[0;34m\u001b[0m\u001b[0;34m\u001b[0m\u001b[0m\n\u001b[1;32m   1012\u001b[0m         \u001b[0mmappedRDD\u001b[0m \u001b[0;34m=\u001b[0m \u001b[0mrdd\u001b[0m\u001b[0;34m.\u001b[0m\u001b[0mmapPartitions\u001b[0m\u001b[0;34m(\u001b[0m\u001b[0mpartitionFunc\u001b[0m\u001b[0;34m)\u001b[0m\u001b[0;34m\u001b[0m\u001b[0m\n\u001b[0;32m-> 1013\u001b[0;31m         \u001b[0msock_info\u001b[0m \u001b[0;34m=\u001b[0m \u001b[0mself\u001b[0m\u001b[0;34m.\u001b[0m\u001b[0m_jvm\u001b[0m\u001b[0;34m.\u001b[0m\u001b[0mPythonRDD\u001b[0m\u001b[0;34m.\u001b[0m\u001b[0mrunJob\u001b[0m\u001b[0;34m(\u001b[0m\u001b[0mself\u001b[0m\u001b[0;34m.\u001b[0m\u001b[0m_jsc\u001b[0m\u001b[0;34m.\u001b[0m\u001b[0msc\u001b[0m\u001b[0;34m(\u001b[0m\u001b[0;34m)\u001b[0m\u001b[0;34m,\u001b[0m \u001b[0mmappedRDD\u001b[0m\u001b[0;34m.\u001b[0m\u001b[0m_jrdd\u001b[0m\u001b[0;34m,\u001b[0m \u001b[0mpartitions\u001b[0m\u001b[0;34m)\u001b[0m\u001b[0;34m\u001b[0m\u001b[0m\n\u001b[0m\u001b[1;32m   1014\u001b[0m         \u001b[0;32mreturn\u001b[0m \u001b[0mlist\u001b[0m\u001b[0;34m(\u001b[0m\u001b[0m_load_from_socket\u001b[0m\u001b[0;34m(\u001b[0m\u001b[0msock_info\u001b[0m\u001b[0;34m,\u001b[0m \u001b[0mmappedRDD\u001b[0m\u001b[0;34m.\u001b[0m\u001b[0m_jrdd_deserializer\u001b[0m\u001b[0;34m)\u001b[0m\u001b[0;34m)\u001b[0m\u001b[0;34m\u001b[0m\u001b[0m\n\u001b[1;32m   1015\u001b[0m \u001b[0;34m\u001b[0m\u001b[0m\n",
      "\u001b[0;32m/home/hadoopuser/anaconda3/lib/python3.6/site-packages/py4j/java_gateway.py\u001b[0m in \u001b[0;36m__call__\u001b[0;34m(self, *args)\u001b[0m\n\u001b[1;32m   1255\u001b[0m         \u001b[0manswer\u001b[0m \u001b[0;34m=\u001b[0m \u001b[0mself\u001b[0m\u001b[0;34m.\u001b[0m\u001b[0mgateway_client\u001b[0m\u001b[0;34m.\u001b[0m\u001b[0msend_command\u001b[0m\u001b[0;34m(\u001b[0m\u001b[0mcommand\u001b[0m\u001b[0;34m)\u001b[0m\u001b[0;34m\u001b[0m\u001b[0m\n\u001b[1;32m   1256\u001b[0m         return_value = get_return_value(\n\u001b[0;32m-> 1257\u001b[0;31m             answer, self.gateway_client, self.target_id, self.name)\n\u001b[0m\u001b[1;32m   1258\u001b[0m \u001b[0;34m\u001b[0m\u001b[0m\n\u001b[1;32m   1259\u001b[0m         \u001b[0;32mfor\u001b[0m \u001b[0mtemp_arg\u001b[0m \u001b[0;32min\u001b[0m \u001b[0mtemp_args\u001b[0m\u001b[0;34m:\u001b[0m\u001b[0;34m\u001b[0m\u001b[0m\n",
      "\u001b[0;32m/home/hadoopuser/anaconda3/lib/python3.6/site-packages/pyspark/sql/utils.py\u001b[0m in \u001b[0;36mdeco\u001b[0;34m(*a, **kw)\u001b[0m\n\u001b[1;32m     61\u001b[0m     \u001b[0;32mdef\u001b[0m \u001b[0mdeco\u001b[0m\u001b[0;34m(\u001b[0m\u001b[0;34m*\u001b[0m\u001b[0ma\u001b[0m\u001b[0;34m,\u001b[0m \u001b[0;34m**\u001b[0m\u001b[0mkw\u001b[0m\u001b[0;34m)\u001b[0m\u001b[0;34m:\u001b[0m\u001b[0;34m\u001b[0m\u001b[0m\n\u001b[1;32m     62\u001b[0m         \u001b[0;32mtry\u001b[0m\u001b[0;34m:\u001b[0m\u001b[0;34m\u001b[0m\u001b[0m\n\u001b[0;32m---> 63\u001b[0;31m             \u001b[0;32mreturn\u001b[0m \u001b[0mf\u001b[0m\u001b[0;34m(\u001b[0m\u001b[0;34m*\u001b[0m\u001b[0ma\u001b[0m\u001b[0;34m,\u001b[0m \u001b[0;34m**\u001b[0m\u001b[0mkw\u001b[0m\u001b[0;34m)\u001b[0m\u001b[0;34m\u001b[0m\u001b[0m\n\u001b[0m\u001b[1;32m     64\u001b[0m         \u001b[0;32mexcept\u001b[0m \u001b[0mpy4j\u001b[0m\u001b[0;34m.\u001b[0m\u001b[0mprotocol\u001b[0m\u001b[0;34m.\u001b[0m\u001b[0mPy4JJavaError\u001b[0m \u001b[0;32mas\u001b[0m \u001b[0me\u001b[0m\u001b[0;34m:\u001b[0m\u001b[0;34m\u001b[0m\u001b[0m\n\u001b[1;32m     65\u001b[0m             \u001b[0ms\u001b[0m \u001b[0;34m=\u001b[0m \u001b[0me\u001b[0m\u001b[0;34m.\u001b[0m\u001b[0mjava_exception\u001b[0m\u001b[0;34m.\u001b[0m\u001b[0mtoString\u001b[0m\u001b[0;34m(\u001b[0m\u001b[0;34m)\u001b[0m\u001b[0;34m\u001b[0m\u001b[0m\n",
      "\u001b[0;32m/home/hadoopuser/anaconda3/lib/python3.6/site-packages/py4j/protocol.py\u001b[0m in \u001b[0;36mget_return_value\u001b[0;34m(answer, gateway_client, target_id, name)\u001b[0m\n\u001b[1;32m    326\u001b[0m                 raise Py4JJavaError(\n\u001b[1;32m    327\u001b[0m                     \u001b[0;34m\"An error occurred while calling {0}{1}{2}.\\n\"\u001b[0m\u001b[0;34m.\u001b[0m\u001b[0;34m\u001b[0m\u001b[0m\n\u001b[0;32m--> 328\u001b[0;31m                     format(target_id, \".\", name), value)\n\u001b[0m\u001b[1;32m    329\u001b[0m             \u001b[0;32melse\u001b[0m\u001b[0;34m:\u001b[0m\u001b[0;34m\u001b[0m\u001b[0m\n\u001b[1;32m    330\u001b[0m                 raise Py4JError(\n",
      "\u001b[0;31mPy4JJavaError\u001b[0m: An error occurred while calling z:org.apache.spark.api.python.PythonRDD.runJob.\n: org.apache.spark.SparkException: Job aborted due to stage failure: Task 0 in stage 0.0 failed 1 times, most recent failure: Lost task 0.0 in stage 0.0 (TID 0, localhost, executor driver): org.apache.spark.api.python.PythonException: Traceback (most recent call last):\n  File \"/home/hadoopuser/anaconda3/lib/python3.6/site-packages/pyspark/python/lib/pyspark.zip/pyspark/worker.py\", line 230, in main\n    process()\n  File \"/home/hadoopuser/anaconda3/lib/python3.6/site-packages/pyspark/python/lib/pyspark.zip/pyspark/worker.py\", line 225, in process\n    serializer.dump_stream(func(split_index, iterator), outfile)\n  File \"/home/hadoopuser/anaconda3/lib/python3.6/site-packages/pyspark/python/lib/pyspark.zip/pyspark/serializers.py\", line 372, in dump_stream\n    vs = list(itertools.islice(iterator, batch))\n  File \"/home/hadoopuser/anaconda3/lib/python3.6/site-packages/pyspark/rdd.py\", line 1371, in takeUpToNumLeft\n    yield next(iterator)\n  File \"/home/hadoopuser/anaconda3/lib/python3.6/site-packages/pyspark/python/lib/pyspark.zip/pyspark/util.py\", line 55, in wrapper\n    return f(*args, **kwargs)\n  File \"<ipython-input-13-bd24de00a52c>\", line 11, in <lambda>\nNameError: name 'Row' is not defined\n\n\tat org.apache.spark.api.python.BasePythonRunner$ReaderIterator.handlePythonException(PythonRunner.scala:298)\n\tat org.apache.spark.api.python.PythonRunner$$anon$1.read(PythonRunner.scala:438)\n\tat org.apache.spark.api.python.PythonRunner$$anon$1.read(PythonRunner.scala:421)\n\tat org.apache.spark.api.python.BasePythonRunner$ReaderIterator.hasNext(PythonRunner.scala:252)\n\tat org.apache.spark.InterruptibleIterator.hasNext(InterruptibleIterator.scala:37)\n\tat scala.collection.Iterator$class.foreach(Iterator.scala:893)\n\tat org.apache.spark.InterruptibleIterator.foreach(InterruptibleIterator.scala:28)\n\tat scala.collection.generic.Growable$class.$plus$plus$eq(Growable.scala:59)\n\tat scala.collection.mutable.ArrayBuffer.$plus$plus$eq(ArrayBuffer.scala:104)\n\tat scala.collection.mutable.ArrayBuffer.$plus$plus$eq(ArrayBuffer.scala:48)\n\tat scala.collection.TraversableOnce$class.to(TraversableOnce.scala:310)\n\tat org.apache.spark.InterruptibleIterator.to(InterruptibleIterator.scala:28)\n\tat scala.collection.TraversableOnce$class.toBuffer(TraversableOnce.scala:302)\n\tat org.apache.spark.InterruptibleIterator.toBuffer(InterruptibleIterator.scala:28)\n\tat scala.collection.TraversableOnce$class.toArray(TraversableOnce.scala:289)\n\tat org.apache.spark.InterruptibleIterator.toArray(InterruptibleIterator.scala:28)\n\tat org.apache.spark.api.python.PythonRDD$$anonfun$3.apply(PythonRDD.scala:149)\n\tat org.apache.spark.api.python.PythonRDD$$anonfun$3.apply(PythonRDD.scala:149)\n\tat org.apache.spark.SparkContext$$anonfun$runJob$5.apply(SparkContext.scala:2074)\n\tat org.apache.spark.SparkContext$$anonfun$runJob$5.apply(SparkContext.scala:2074)\n\tat org.apache.spark.scheduler.ResultTask.runTask(ResultTask.scala:87)\n\tat org.apache.spark.scheduler.Task.run(Task.scala:109)\n\tat org.apache.spark.executor.Executor$TaskRunner.run(Executor.scala:345)\n\tat java.util.concurrent.ThreadPoolExecutor.runWorker(ThreadPoolExecutor.java:1149)\n\tat java.util.concurrent.ThreadPoolExecutor$Worker.run(ThreadPoolExecutor.java:624)\n\tat java.lang.Thread.run(Thread.java:748)\n\nDriver stacktrace:\n\tat org.apache.spark.scheduler.DAGScheduler.org$apache$spark$scheduler$DAGScheduler$$failJobAndIndependentStages(DAGScheduler.scala:1602)\n\tat org.apache.spark.scheduler.DAGScheduler$$anonfun$abortStage$1.apply(DAGScheduler.scala:1590)\n\tat org.apache.spark.scheduler.DAGScheduler$$anonfun$abortStage$1.apply(DAGScheduler.scala:1589)\n\tat scala.collection.mutable.ResizableArray$class.foreach(ResizableArray.scala:59)\n\tat scala.collection.mutable.ArrayBuffer.foreach(ArrayBuffer.scala:48)\n\tat org.apache.spark.scheduler.DAGScheduler.abortStage(DAGScheduler.scala:1589)\n\tat org.apache.spark.scheduler.DAGScheduler$$anonfun$handleTaskSetFailed$1.apply(DAGScheduler.scala:831)\n\tat org.apache.spark.scheduler.DAGScheduler$$anonfun$handleTaskSetFailed$1.apply(DAGScheduler.scala:831)\n\tat scala.Option.foreach(Option.scala:257)\n\tat org.apache.spark.scheduler.DAGScheduler.handleTaskSetFailed(DAGScheduler.scala:831)\n\tat org.apache.spark.scheduler.DAGSchedulerEventProcessLoop.doOnReceive(DAGScheduler.scala:1823)\n\tat org.apache.spark.scheduler.DAGSchedulerEventProcessLoop.onReceive(DAGScheduler.scala:1772)\n\tat org.apache.spark.scheduler.DAGSchedulerEventProcessLoop.onReceive(DAGScheduler.scala:1761)\n\tat org.apache.spark.util.EventLoop$$anon$1.run(EventLoop.scala:48)\n\tat org.apache.spark.scheduler.DAGScheduler.runJob(DAGScheduler.scala:642)\n\tat org.apache.spark.SparkContext.runJob(SparkContext.scala:2034)\n\tat org.apache.spark.SparkContext.runJob(SparkContext.scala:2055)\n\tat org.apache.spark.SparkContext.runJob(SparkContext.scala:2074)\n\tat org.apache.spark.api.python.PythonRDD$.runJob(PythonRDD.scala:149)\n\tat org.apache.spark.api.python.PythonRDD.runJob(PythonRDD.scala)\n\tat sun.reflect.NativeMethodAccessorImpl.invoke0(Native Method)\n\tat sun.reflect.NativeMethodAccessorImpl.invoke(NativeMethodAccessorImpl.java:62)\n\tat sun.reflect.DelegatingMethodAccessorImpl.invoke(DelegatingMethodAccessorImpl.java:43)\n\tat java.lang.reflect.Method.invoke(Method.java:498)\n\tat py4j.reflection.MethodInvoker.invoke(MethodInvoker.java:244)\n\tat py4j.reflection.ReflectionEngine.invoke(ReflectionEngine.java:357)\n\tat py4j.Gateway.invoke(Gateway.java:282)\n\tat py4j.commands.AbstractCommand.invokeMethod(AbstractCommand.java:132)\n\tat py4j.commands.CallCommand.execute(CallCommand.java:79)\n\tat py4j.GatewayConnection.run(GatewayConnection.java:238)\n\tat java.lang.Thread.run(Thread.java:748)\nCaused by: org.apache.spark.api.python.PythonException: Traceback (most recent call last):\n  File \"/home/hadoopuser/anaconda3/lib/python3.6/site-packages/pyspark/python/lib/pyspark.zip/pyspark/worker.py\", line 230, in main\n    process()\n  File \"/home/hadoopuser/anaconda3/lib/python3.6/site-packages/pyspark/python/lib/pyspark.zip/pyspark/worker.py\", line 225, in process\n    serializer.dump_stream(func(split_index, iterator), outfile)\n  File \"/home/hadoopuser/anaconda3/lib/python3.6/site-packages/pyspark/python/lib/pyspark.zip/pyspark/serializers.py\", line 372, in dump_stream\n    vs = list(itertools.islice(iterator, batch))\n  File \"/home/hadoopuser/anaconda3/lib/python3.6/site-packages/pyspark/rdd.py\", line 1371, in takeUpToNumLeft\n    yield next(iterator)\n  File \"/home/hadoopuser/anaconda3/lib/python3.6/site-packages/pyspark/python/lib/pyspark.zip/pyspark/util.py\", line 55, in wrapper\n    return f(*args, **kwargs)\n  File \"<ipython-input-13-bd24de00a52c>\", line 11, in <lambda>\nNameError: name 'Row' is not defined\n\n\tat org.apache.spark.api.python.BasePythonRunner$ReaderIterator.handlePythonException(PythonRunner.scala:298)\n\tat org.apache.spark.api.python.PythonRunner$$anon$1.read(PythonRunner.scala:438)\n\tat org.apache.spark.api.python.PythonRunner$$anon$1.read(PythonRunner.scala:421)\n\tat org.apache.spark.api.python.BasePythonRunner$ReaderIterator.hasNext(PythonRunner.scala:252)\n\tat org.apache.spark.InterruptibleIterator.hasNext(InterruptibleIterator.scala:37)\n\tat scala.collection.Iterator$class.foreach(Iterator.scala:893)\n\tat org.apache.spark.InterruptibleIterator.foreach(InterruptibleIterator.scala:28)\n\tat scala.collection.generic.Growable$class.$plus$plus$eq(Growable.scala:59)\n\tat scala.collection.mutable.ArrayBuffer.$plus$plus$eq(ArrayBuffer.scala:104)\n\tat scala.collection.mutable.ArrayBuffer.$plus$plus$eq(ArrayBuffer.scala:48)\n\tat scala.collection.TraversableOnce$class.to(TraversableOnce.scala:310)\n\tat org.apache.spark.InterruptibleIterator.to(InterruptibleIterator.scala:28)\n\tat scala.collection.TraversableOnce$class.toBuffer(TraversableOnce.scala:302)\n\tat org.apache.spark.InterruptibleIterator.toBuffer(InterruptibleIterator.scala:28)\n\tat scala.collection.TraversableOnce$class.toArray(TraversableOnce.scala:289)\n\tat org.apache.spark.InterruptibleIterator.toArray(InterruptibleIterator.scala:28)\n\tat org.apache.spark.api.python.PythonRDD$$anonfun$3.apply(PythonRDD.scala:149)\n\tat org.apache.spark.api.python.PythonRDD$$anonfun$3.apply(PythonRDD.scala:149)\n\tat org.apache.spark.SparkContext$$anonfun$runJob$5.apply(SparkContext.scala:2074)\n\tat org.apache.spark.SparkContext$$anonfun$runJob$5.apply(SparkContext.scala:2074)\n\tat org.apache.spark.scheduler.ResultTask.runTask(ResultTask.scala:87)\n\tat org.apache.spark.scheduler.Task.run(Task.scala:109)\n\tat org.apache.spark.executor.Executor$TaskRunner.run(Executor.scala:345)\n\tat java.util.concurrent.ThreadPoolExecutor.runWorker(ThreadPoolExecutor.java:1149)\n\tat java.util.concurrent.ThreadPoolExecutor$Worker.run(ThreadPoolExecutor.java:624)\n\t... 1 more\n"
     ]
    }
   ],
   "source": [
    "sc.stop()\n",
    "from pyspark import SparkContext\n",
    "sc =SparkContext()\n",
    "\n",
    "\n",
    "\n",
    "textFile = sc.textFile(\"file:///home/hadoopuser/input.txt\")\n",
    "\n",
    "\n",
    "# Creates a DataFrame having a single column named \"line\"\n",
    "df = textFile.map(lambda r: Row(r)).toDF([\"line\"])\n",
    "errors = df.filter(col(\"line\").like(\"%ERROR%\"))\n",
    "# Counts all the errors\n",
    "errors.count()\n",
    "# Counts errors mentioning MySQL\n",
    "errors.filter(col(\"line\").like(\"%MySQL%\")).count()\n",
    "# Fetches the MySQL errors as an array of strings\n",
    "errors.filter(col(\"line\").like(\"%MySQL%\")).collect()"
   ]
  },
  {
   "cell_type": "code",
   "execution_count": 57,
   "metadata": {},
   "outputs": [],
   "source": [
    "# #didnt work\n",
    "# sc.stop()\n",
    "# from pyspark import SparkContext\n",
    "# sc =SparkContext()\n",
    "# df = spark.createDataFrame([ (1, 1), (1, 3), (2, 1), (3, 2), (3, 3) ], [\"user_id\", \"genre_id\"])"
   ]
  },
  {
   "cell_type": "code",
   "execution_count": 23,
   "metadata": {},
   "outputs": [
    {
     "name": "stdout",
     "output_type": "stream",
     "text": [
      "+-------+--------+\n",
      "|user_id|genre_id|\n",
      "+-------+--------+\n",
      "|      1|       1|\n",
      "|      1|       3|\n",
      "|      2|       1|\n",
      "|      3|       2|\n",
      "|      3|       3|\n",
      "+-------+--------+\n",
      "\n"
     ]
    }
   ],
   "source": [
    "from pyspark.sql import SQLContext\n",
    "\n",
    "sqlContext = SQLContext(sc)\n",
    "df  = sqlContext.createDataFrame([ (1, 1), (1, 3), (2, 1), (3, 2), (3, 3) ], [\"user_id\", \"genre_id\"])\n",
    "df.show()"
   ]
  },
  {
   "cell_type": "code",
   "execution_count": 24,
   "metadata": {},
   "outputs": [
    {
     "name": "stdout",
     "output_type": "stream",
     "text": [
      "+-------+-----+\n",
      "|user_id|count|\n",
      "+-------+-----+\n",
      "|      1|    2|\n",
      "|      3|    2|\n",
      "|      2|    1|\n",
      "+-------+-----+\n",
      "\n"
     ]
    }
   ],
   "source": [
    "df.groupBy(\"user_id\").count().show()"
   ]
  },
  {
   "cell_type": "code",
   "execution_count": 27,
   "metadata": {},
   "outputs": [],
   "source": [
    "# scala> val df = Seq((\"a\", 1), (\"b\", 2), (\"a\", 1), (\"c\", 5), (\"b\", 2)).toDF(\"id\", \"value\")\n",
    "# scala> df.limit(3).groupBy(\"id\").count().show()"
   ]
  },
  {
   "cell_type": "code",
   "execution_count": 34,
   "metadata": {},
   "outputs": [
    {
     "ename": "TypeError",
     "evalue": "Can not infer schema for type: <class 'str'>",
     "output_type": "error",
     "traceback": [
      "\u001b[0;31m---------------------------------------------------------------------------\u001b[0m",
      "\u001b[0;31mTypeError\u001b[0m                                 Traceback (most recent call last)",
      "\u001b[0;32m<ipython-input-34-5185ecfa5468>\u001b[0m in \u001b[0;36m<module>\u001b[0;34m()\u001b[0m\n\u001b[1;32m      6\u001b[0m \u001b[0;31m#RDDread.Collect()\u001b[0m\u001b[0;34m\u001b[0m\u001b[0;34m\u001b[0m\u001b[0m\n\u001b[1;32m      7\u001b[0m \u001b[0;34m\u001b[0m\u001b[0m\n\u001b[0;32m----> 8\u001b[0;31m \u001b[0ma_df\u001b[0m \u001b[0;34m=\u001b[0m \u001b[0mRDDread\u001b[0m\u001b[0;34m.\u001b[0m\u001b[0mtoDF\u001b[0m\u001b[0;34m(\u001b[0m\u001b[0;34m)\u001b[0m\u001b[0;34m\u001b[0m\u001b[0m\n\u001b[0m",
      "\u001b[0;32m/home/hadoopuser/anaconda3/lib/python3.6/site-packages/pyspark/sql/session.py\u001b[0m in \u001b[0;36mtoDF\u001b[0;34m(self, schema, sampleRatio)\u001b[0m\n\u001b[1;32m     56\u001b[0m         \u001b[0;34m[\u001b[0m\u001b[0mRow\u001b[0m\u001b[0;34m(\u001b[0m\u001b[0mname\u001b[0m\u001b[0;34m=\u001b[0m\u001b[0;34mu'Alice'\u001b[0m\u001b[0;34m,\u001b[0m \u001b[0mage\u001b[0m\u001b[0;34m=\u001b[0m\u001b[0;36m1\u001b[0m\u001b[0;34m)\u001b[0m\u001b[0;34m]\u001b[0m\u001b[0;34m\u001b[0m\u001b[0m\n\u001b[1;32m     57\u001b[0m         \"\"\"\n\u001b[0;32m---> 58\u001b[0;31m         \u001b[0;32mreturn\u001b[0m \u001b[0msparkSession\u001b[0m\u001b[0;34m.\u001b[0m\u001b[0mcreateDataFrame\u001b[0m\u001b[0;34m(\u001b[0m\u001b[0mself\u001b[0m\u001b[0;34m,\u001b[0m \u001b[0mschema\u001b[0m\u001b[0;34m,\u001b[0m \u001b[0msampleRatio\u001b[0m\u001b[0;34m)\u001b[0m\u001b[0;34m\u001b[0m\u001b[0m\n\u001b[0m\u001b[1;32m     59\u001b[0m \u001b[0;34m\u001b[0m\u001b[0m\n\u001b[1;32m     60\u001b[0m     \u001b[0mRDD\u001b[0m\u001b[0;34m.\u001b[0m\u001b[0mtoDF\u001b[0m \u001b[0;34m=\u001b[0m \u001b[0mtoDF\u001b[0m\u001b[0;34m\u001b[0m\u001b[0m\n",
      "\u001b[0;32m/home/hadoopuser/anaconda3/lib/python3.6/site-packages/pyspark/sql/session.py\u001b[0m in \u001b[0;36mcreateDataFrame\u001b[0;34m(self, data, schema, samplingRatio, verifySchema)\u001b[0m\n\u001b[1;32m    687\u001b[0m \u001b[0;34m\u001b[0m\u001b[0m\n\u001b[1;32m    688\u001b[0m         \u001b[0;32mif\u001b[0m \u001b[0misinstance\u001b[0m\u001b[0;34m(\u001b[0m\u001b[0mdata\u001b[0m\u001b[0;34m,\u001b[0m \u001b[0mRDD\u001b[0m\u001b[0;34m)\u001b[0m\u001b[0;34m:\u001b[0m\u001b[0;34m\u001b[0m\u001b[0m\n\u001b[0;32m--> 689\u001b[0;31m             \u001b[0mrdd\u001b[0m\u001b[0;34m,\u001b[0m \u001b[0mschema\u001b[0m \u001b[0;34m=\u001b[0m \u001b[0mself\u001b[0m\u001b[0;34m.\u001b[0m\u001b[0m_createFromRDD\u001b[0m\u001b[0;34m(\u001b[0m\u001b[0mdata\u001b[0m\u001b[0;34m.\u001b[0m\u001b[0mmap\u001b[0m\u001b[0;34m(\u001b[0m\u001b[0mprepare\u001b[0m\u001b[0;34m)\u001b[0m\u001b[0;34m,\u001b[0m \u001b[0mschema\u001b[0m\u001b[0;34m,\u001b[0m \u001b[0msamplingRatio\u001b[0m\u001b[0;34m)\u001b[0m\u001b[0;34m\u001b[0m\u001b[0m\n\u001b[0m\u001b[1;32m    690\u001b[0m         \u001b[0;32melse\u001b[0m\u001b[0;34m:\u001b[0m\u001b[0;34m\u001b[0m\u001b[0m\n\u001b[1;32m    691\u001b[0m             \u001b[0mrdd\u001b[0m\u001b[0;34m,\u001b[0m \u001b[0mschema\u001b[0m \u001b[0;34m=\u001b[0m \u001b[0mself\u001b[0m\u001b[0;34m.\u001b[0m\u001b[0m_createFromLocal\u001b[0m\u001b[0;34m(\u001b[0m\u001b[0mmap\u001b[0m\u001b[0;34m(\u001b[0m\u001b[0mprepare\u001b[0m\u001b[0;34m,\u001b[0m \u001b[0mdata\u001b[0m\u001b[0;34m)\u001b[0m\u001b[0;34m,\u001b[0m \u001b[0mschema\u001b[0m\u001b[0;34m)\u001b[0m\u001b[0;34m\u001b[0m\u001b[0m\n",
      "\u001b[0;32m/home/hadoopuser/anaconda3/lib/python3.6/site-packages/pyspark/sql/session.py\u001b[0m in \u001b[0;36m_createFromRDD\u001b[0;34m(self, rdd, schema, samplingRatio)\u001b[0m\n\u001b[1;32m    382\u001b[0m         \"\"\"\n\u001b[1;32m    383\u001b[0m         \u001b[0;32mif\u001b[0m \u001b[0mschema\u001b[0m \u001b[0;32mis\u001b[0m \u001b[0;32mNone\u001b[0m \u001b[0;32mor\u001b[0m \u001b[0misinstance\u001b[0m\u001b[0;34m(\u001b[0m\u001b[0mschema\u001b[0m\u001b[0;34m,\u001b[0m \u001b[0;34m(\u001b[0m\u001b[0mlist\u001b[0m\u001b[0;34m,\u001b[0m \u001b[0mtuple\u001b[0m\u001b[0;34m)\u001b[0m\u001b[0;34m)\u001b[0m\u001b[0;34m:\u001b[0m\u001b[0;34m\u001b[0m\u001b[0m\n\u001b[0;32m--> 384\u001b[0;31m             \u001b[0mstruct\u001b[0m \u001b[0;34m=\u001b[0m \u001b[0mself\u001b[0m\u001b[0;34m.\u001b[0m\u001b[0m_inferSchema\u001b[0m\u001b[0;34m(\u001b[0m\u001b[0mrdd\u001b[0m\u001b[0;34m,\u001b[0m \u001b[0msamplingRatio\u001b[0m\u001b[0;34m,\u001b[0m \u001b[0mnames\u001b[0m\u001b[0;34m=\u001b[0m\u001b[0mschema\u001b[0m\u001b[0;34m)\u001b[0m\u001b[0;34m\u001b[0m\u001b[0m\n\u001b[0m\u001b[1;32m    385\u001b[0m             \u001b[0mconverter\u001b[0m \u001b[0;34m=\u001b[0m \u001b[0m_create_converter\u001b[0m\u001b[0;34m(\u001b[0m\u001b[0mstruct\u001b[0m\u001b[0;34m)\u001b[0m\u001b[0;34m\u001b[0m\u001b[0m\n\u001b[1;32m    386\u001b[0m             \u001b[0mrdd\u001b[0m \u001b[0;34m=\u001b[0m \u001b[0mrdd\u001b[0m\u001b[0;34m.\u001b[0m\u001b[0mmap\u001b[0m\u001b[0;34m(\u001b[0m\u001b[0mconverter\u001b[0m\u001b[0;34m)\u001b[0m\u001b[0;34m\u001b[0m\u001b[0m\n",
      "\u001b[0;32m/home/hadoopuser/anaconda3/lib/python3.6/site-packages/pyspark/sql/session.py\u001b[0m in \u001b[0;36m_inferSchema\u001b[0;34m(self, rdd, samplingRatio, names)\u001b[0m\n\u001b[1;32m    362\u001b[0m \u001b[0;34m\u001b[0m\u001b[0m\n\u001b[1;32m    363\u001b[0m         \u001b[0;32mif\u001b[0m \u001b[0msamplingRatio\u001b[0m \u001b[0;32mis\u001b[0m \u001b[0;32mNone\u001b[0m\u001b[0;34m:\u001b[0m\u001b[0;34m\u001b[0m\u001b[0m\n\u001b[0;32m--> 364\u001b[0;31m             \u001b[0mschema\u001b[0m \u001b[0;34m=\u001b[0m \u001b[0m_infer_schema\u001b[0m\u001b[0;34m(\u001b[0m\u001b[0mfirst\u001b[0m\u001b[0;34m,\u001b[0m \u001b[0mnames\u001b[0m\u001b[0;34m=\u001b[0m\u001b[0mnames\u001b[0m\u001b[0;34m)\u001b[0m\u001b[0;34m\u001b[0m\u001b[0m\n\u001b[0m\u001b[1;32m    365\u001b[0m             \u001b[0;32mif\u001b[0m \u001b[0m_has_nulltype\u001b[0m\u001b[0;34m(\u001b[0m\u001b[0mschema\u001b[0m\u001b[0;34m)\u001b[0m\u001b[0;34m:\u001b[0m\u001b[0;34m\u001b[0m\u001b[0m\n\u001b[1;32m    366\u001b[0m                 \u001b[0;32mfor\u001b[0m \u001b[0mrow\u001b[0m \u001b[0;32min\u001b[0m \u001b[0mrdd\u001b[0m\u001b[0;34m.\u001b[0m\u001b[0mtake\u001b[0m\u001b[0;34m(\u001b[0m\u001b[0;36m100\u001b[0m\u001b[0;34m)\u001b[0m\u001b[0;34m[\u001b[0m\u001b[0;36m1\u001b[0m\u001b[0;34m:\u001b[0m\u001b[0;34m]\u001b[0m\u001b[0;34m:\u001b[0m\u001b[0;34m\u001b[0m\u001b[0m\n",
      "\u001b[0;32m/home/hadoopuser/anaconda3/lib/python3.6/site-packages/pyspark/sql/types.py\u001b[0m in \u001b[0;36m_infer_schema\u001b[0;34m(row, names)\u001b[0m\n\u001b[1;32m   1092\u001b[0m \u001b[0;34m\u001b[0m\u001b[0m\n\u001b[1;32m   1093\u001b[0m     \u001b[0;32melse\u001b[0m\u001b[0;34m:\u001b[0m\u001b[0;34m\u001b[0m\u001b[0m\n\u001b[0;32m-> 1094\u001b[0;31m         \u001b[0;32mraise\u001b[0m \u001b[0mTypeError\u001b[0m\u001b[0;34m(\u001b[0m\u001b[0;34m\"Can not infer schema for type: %s\"\u001b[0m \u001b[0;34m%\u001b[0m \u001b[0mtype\u001b[0m\u001b[0;34m(\u001b[0m\u001b[0mrow\u001b[0m\u001b[0;34m)\u001b[0m\u001b[0;34m)\u001b[0m\u001b[0;34m\u001b[0m\u001b[0m\n\u001b[0m\u001b[1;32m   1095\u001b[0m \u001b[0;34m\u001b[0m\u001b[0m\n\u001b[1;32m   1096\u001b[0m     \u001b[0mfields\u001b[0m \u001b[0;34m=\u001b[0m \u001b[0;34m[\u001b[0m\u001b[0mStructField\u001b[0m\u001b[0;34m(\u001b[0m\u001b[0mk\u001b[0m\u001b[0;34m,\u001b[0m \u001b[0m_infer_type\u001b[0m\u001b[0;34m(\u001b[0m\u001b[0mv\u001b[0m\u001b[0;34m)\u001b[0m\u001b[0;34m,\u001b[0m \u001b[0;32mTrue\u001b[0m\u001b[0;34m)\u001b[0m \u001b[0;32mfor\u001b[0m \u001b[0mk\u001b[0m\u001b[0;34m,\u001b[0m \u001b[0mv\u001b[0m \u001b[0;32min\u001b[0m \u001b[0mitems\u001b[0m\u001b[0;34m]\u001b[0m\u001b[0;34m\u001b[0m\u001b[0m\n",
      "\u001b[0;31mTypeError\u001b[0m: Can not infer schema for type: <class 'str'>"
     ]
    }
   ],
   "source": [
    "sc.stop()\n",
    "from pyspark import SparkContext\n",
    "sc =SparkContext()\n",
    "\n",
    "RDDread = sc.textFile(\"file:///home/hadoopuser/input.txt\")\n",
    "RDDread.Collect()\n",
    "\n"
   ]
  },
  {
   "cell_type": "code",
   "execution_count": 38,
   "metadata": {},
   "outputs": [
    {
     "name": "stdout",
     "output_type": "stream",
     "text": [
      "Lines with a: 4, lines with b: 2\n"
     ]
    }
   ],
   "source": [
    "sc.stop()\n",
    "\n",
    "from pyspark import SparkContext\n",
    "logFile = \"file:///home/hadoopuser/input.txt\" \n",
    "sc = SparkContext(\"local\", \"first app\")\n",
    "logData = sc.textFile(logFile).cache()\n",
    "numAs = logData.filter(lambda s: 'a' in s).count()\n",
    "numBs = logData.filter(lambda s: 'b' in s).count()\n",
    "print (\"Lines with a: %i, lines with b: %i\" % (numAs, numBs))"
   ]
  },
  {
   "cell_type": "code",
   "execution_count": 39,
   "metadata": {},
   "outputs": [],
   "source": [
    "words = sc.parallelize (\n",
    "   [\"scala\", \n",
    "   \"java\", \n",
    "   \"hadoop\", \n",
    "   \"spark\", \n",
    "   \"akka\",\n",
    "   \"spark vs hadoop\", \n",
    "   \"pyspark\",\n",
    "   \"pyspark and spark\"]\n",
    ")"
   ]
  },
  {
   "cell_type": "code",
   "execution_count": 41,
   "metadata": {},
   "outputs": [
    {
     "name": "stdout",
     "output_type": "stream",
     "text": [
      "Number of elements in RDD -> 8\n"
     ]
    }
   ],
   "source": [
    "sc.stop()\n",
    "from pyspark import SparkContext\n",
    "sc = SparkContext(\"local\", \"count app\")\n",
    "words = sc.parallelize (\n",
    "   [\"scala\", \n",
    "   \"java\", \n",
    "   \"hadoop\", \n",
    "   \"spark\", \n",
    "   \"akka\",\n",
    "   \"spark vs hadoop\", \n",
    "   \"pyspark\",\n",
    "   \"pyspark and spark\"]\n",
    ")\n",
    "counts = words.count()\n",
    "print (\"Number of elements in RDD -> %i\" % (counts))"
   ]
  },
  {
   "cell_type": "code",
   "execution_count": 43,
   "metadata": {},
   "outputs": [
    {
     "name": "stdout",
     "output_type": "stream",
     "text": [
      "Elements in RDD -> ['scala', 'java', 'hadoop', 'spark', 'akka', 'spark vs hadoop', 'pyspark', 'pyspark and spark']\n"
     ]
    }
   ],
   "source": [
    "sc.stop()\n",
    "\n",
    "from pyspark import SparkContext\n",
    "sc = SparkContext(\"local\", \"Collect app\")\n",
    "words = sc.parallelize (\n",
    "   [\"scala\", \n",
    "   \"java\", \n",
    "   \"hadoop\", \n",
    "   \"spark\", \n",
    "   \"akka\",\n",
    "   \"spark vs hadoop\", \n",
    "   \"pyspark\",\n",
    "   \"pyspark and spark\"]\n",
    ")\n",
    "coll = words.collect()\n",
    "print (\"Elements in RDD -> %s\" % (coll))"
   ]
  },
  {
   "cell_type": "code",
   "execution_count": 51,
   "metadata": {},
   "outputs": [],
   "source": [
    "sc.stop()\n",
    "\n",
    "from pyspark import SparkContext\n",
    "sc = SparkContext(\"local\", \"ForEach app\")\n",
    "words = sc.parallelize (\n",
    "   [\"scala\", \n",
    "   \"java\", \n",
    "   \"hadoop\", \n",
    "   \"spark\", \n",
    "   \"akka\",\n",
    "   \"spark vs hadoop\", \n",
    "   \"pyspark\",\n",
    "   \"pyspark and spark\"]\n",
    ")\n",
    "def f1(x): \n",
    "    print(x, \"hi\")\n",
    "fore = words.foreach(f1) "
   ]
  },
  {
   "cell_type": "code",
   "execution_count": 50,
   "metadata": {},
   "outputs": [
    {
     "name": "stdout",
     "output_type": "stream",
     "text": [
      "Fitered RDD -> ['spark', 'spark vs hadoop', 'pyspark', 'pyspark and spark']\n"
     ]
    }
   ],
   "source": [
    "sc.stop()\n",
    "\n",
    "from pyspark import SparkContext\n",
    "sc = SparkContext(\"local\", \"Filter app\")\n",
    "words = sc.parallelize (\n",
    "   [\"scala\", \n",
    "   \"java\", \n",
    "   \"hadoop\", \n",
    "   \"spark\", \n",
    "   \"akka\",\n",
    "   \"spark vs hadoop\", \n",
    "   \"pyspark\",\n",
    "   \"pyspark and spark\"]\n",
    ")\n",
    "words_filter = words.filter(lambda x: 'spark' in x)\n",
    "filtered = words_filter.collect()\n",
    "print (\"Fitered RDD -> %s\" % (filtered))"
   ]
  },
  {
   "cell_type": "code",
   "execution_count": 53,
   "metadata": {},
   "outputs": [
    {
     "name": "stdout",
     "output_type": "stream",
     "text": [
      "Adding all the elements -> 15\n"
     ]
    }
   ],
   "source": [
    "\n",
    "sc.stop()\n",
    "\n",
    "from pyspark import SparkContext\n",
    "from operator import add\n",
    "sc = SparkContext(\"local\", \"Reduce app\")\n",
    "nums = sc.parallelize([1, 2, 3, 4, 5])\n",
    "adding = nums.reduce(add)\n",
    "print (\"Adding all the elements -> %i\" % (adding))"
   ]
  },
  {
   "cell_type": "code",
   "execution_count": 56,
   "metadata": {},
   "outputs": [
    {
     "name": "stdout",
     "output_type": "stream",
     "text": [
      "Stored data -> ['scala', 'java', 'hadoop', 'spark', 'akka']\n",
      "Printing a particular element in RDD -> hadoop\n"
     ]
    }
   ],
   "source": [
    "\n",
    "\n",
    "sc.stop()\n",
    "from pyspark import SparkContext \n",
    "sc = SparkContext(\"local\", \"Broadcast app\") \n",
    "words_new = sc.broadcast([\"scala\", \"java\", \"hadoop\", \"spark\", \"akka\"]) \n",
    "data = words_new.value \n",
    "print (\"Stored data -> %s\" % (data) )\n",
    "elem = words_new.value[2] \n",
    "print (\"Printing a particular element in RDD -> %s\" % (elem))"
   ]
  },
  {
   "cell_type": "code",
   "execution_count": 58,
   "metadata": {},
   "outputs": [
    {
     "data": {
      "text/plain": [
       "[Row(id=0),\n",
       " Row(id=1),\n",
       " Row(id=2),\n",
       " Row(id=3),\n",
       " Row(id=4),\n",
       " Row(id=5),\n",
       " Row(id=6),\n",
       " Row(id=7),\n",
       " Row(id=8),\n",
       " Row(id=9)]"
      ]
     },
     "execution_count": 58,
     "metadata": {},
     "output_type": "execute_result"
    }
   ],
   "source": [
    "# Start pyspark via provided command\n",
    "import pyspark\n",
    "\n",
    "# Below code is Spark 2+\n",
    "spark = pyspark.sql.SparkSession.builder.appName('test').getOrCreate()\n",
    "\n",
    "spark.range(10).collect()\n"
   ]
  },
  {
   "cell_type": "code",
   "execution_count": 60,
   "metadata": {},
   "outputs": [
    {
     "name": "stdout",
     "output_type": "stream",
     "text": [
      "+------------+\n",
      "|databaseName|\n",
      "+------------+\n",
      "|     default|\n",
      "+------------+\n",
      "\n"
     ]
    }
   ],
   "source": [
    "\n",
    "\n",
    "sqlContext.sql(\"show databases\").show()\n",
    "\n"
   ]
  },
  {
   "cell_type": "code",
   "execution_count": 61,
   "metadata": {},
   "outputs": [
    {
     "data": {
      "text/plain": [
       "DataFrame[]"
      ]
     },
     "execution_count": 61,
     "metadata": {},
     "output_type": "execute_result"
    }
   ],
   "source": [
    "sqlContext.sql('create database movies')"
   ]
  },
  {
   "cell_type": "code",
   "execution_count": 62,
   "metadata": {},
   "outputs": [
    {
     "name": "stdout",
     "output_type": "stream",
     "text": [
      "+------------+\n",
      "|databaseName|\n",
      "+------------+\n",
      "|     default|\n",
      "|      movies|\n",
      "+------------+\n",
      "\n"
     ]
    }
   ],
   "source": [
    "sqlContext.sql('show databases').show()"
   ]
  },
  {
   "cell_type": "code",
   "execution_count": 63,
   "metadata": {},
   "outputs": [
    {
     "name": "stdout",
     "output_type": "stream",
     "text": [
      "--2018-10-04 13:14:07--  http://files.grouplens.org/datasets/movielens/ml-latest.zip\n",
      "Resolving files.grouplens.org (files.grouplens.org)... 128.101.34.235\n",
      "Connecting to files.grouplens.org (files.grouplens.org)|128.101.34.235|:80... connected.\n",
      "HTTP request sent, awaiting response... 200 OK\n",
      "Length: 277113433 (264M) [application/zip]\n",
      "Saving to: ‘ml-latest.zip’\n",
      "\n",
      "ml-latest.zip       100%[===================>] 264.28M  8.25MB/s    in 32s     \n",
      "\n",
      "2018-10-05 12:24:56 (8.17 MB/s) - ‘ml-latest.zip’ saved [277113433/277113433]\n",
      "\n"
     ]
    }
   ],
   "source": [
    "! wget http://files.grouplens.org/datasets/movielens/ml-latest.zip"
   ]
  },
  {
   "cell_type": "code",
   "execution_count": 65,
   "metadata": {},
   "outputs": [
    {
     "data": {
      "text/plain": [
       "DataFrame[]"
      ]
     },
     "execution_count": 65,
     "metadata": {},
     "output_type": "execute_result"
    }
   ],
   "source": [
    "sqlContext.sql('use movies')"
   ]
  },
  {
   "cell_type": "code",
   "execution_count": 71,
   "metadata": {},
   "outputs": [
    {
     "data": {
      "text/plain": [
       "pyspark.rdd.RDD"
      ]
     },
     "execution_count": 71,
     "metadata": {},
     "output_type": "execute_result"
    }
   ],
   "source": [
    "data = sc.textFile('input.txt')\n",
    "\n",
    "type(data)\n"
   ]
  },
  {
   "cell_type": "code",
   "execution_count": 75,
   "metadata": {},
   "outputs": [
    {
     "ename": "Py4JError",
     "evalue": "An error occurred while calling o1015.read",
     "output_type": "error",
     "traceback": [
      "\u001b[0;31m---------------------------------------------------------------------------\u001b[0m",
      "\u001b[0;31mPy4JError\u001b[0m                                 Traceback (most recent call last)",
      "\u001b[0;32m<ipython-input-75-05ef1fd98fa6>\u001b[0m in \u001b[0;36m<module>\u001b[0;34m()\u001b[0m\n\u001b[0;32m----> 1\u001b[0;31m \u001b[0mdataframe2\u001b[0m \u001b[0;34m=\u001b[0m \u001b[0mspark\u001b[0m\u001b[0;34m.\u001b[0m\u001b[0mread\u001b[0m\u001b[0;34m.\u001b[0m\u001b[0mformat\u001b[0m\u001b[0;34m(\u001b[0m\u001b[0;34m'csv'\u001b[0m\u001b[0;34m)\u001b[0m\u001b[0;34m.\u001b[0m\u001b[0moption\u001b[0m\u001b[0;34m(\u001b[0m\u001b[0;34m'header'\u001b[0m\u001b[0;34m,\u001b[0m\u001b[0;34m'true'\u001b[0m\u001b[0;34m)\u001b[0m\u001b[0;34m.\u001b[0m\u001b[0moption\u001b[0m\u001b[0;34m(\u001b[0m\u001b[0;34m'mode'\u001b[0m\u001b[0;34m,\u001b[0m\u001b[0;34m'DROPMALFORMED'\u001b[0m\u001b[0;34m)\u001b[0m\u001b[0;34m.\u001b[0m\u001b[0mload\u001b[0m\u001b[0;34m(\u001b[0m\u001b[0;34m'input.txt'\u001b[0m\u001b[0;34m)\u001b[0m\u001b[0;34m\u001b[0m\u001b[0m\n\u001b[0m\u001b[1;32m      2\u001b[0m \u001b[0;34m\u001b[0m\u001b[0m\n\u001b[1;32m      3\u001b[0m \u001b[0mtype\u001b[0m\u001b[0;34m(\u001b[0m\u001b[0mdataframe2\u001b[0m\u001b[0;34m)\u001b[0m\u001b[0;34m\u001b[0m\u001b[0m\n",
      "\u001b[0;32m/home/hadoopuser/anaconda3/lib/python3.6/site-packages/pyspark/sql/session.py\u001b[0m in \u001b[0;36mread\u001b[0;34m(self)\u001b[0m\n\u001b[1;32m    732\u001b[0m         \u001b[0;34m:\u001b[0m\u001b[0;32mreturn\u001b[0m\u001b[0;34m:\u001b[0m \u001b[0;34m:\u001b[0m\u001b[0;32mclass\u001b[0m\u001b[0;34m:\u001b[0m\u001b[0;31m`\u001b[0m\u001b[0mDataFrameReader\u001b[0m\u001b[0;31m`\u001b[0m\u001b[0;34m\u001b[0m\u001b[0m\n\u001b[1;32m    733\u001b[0m         \"\"\"\n\u001b[0;32m--> 734\u001b[0;31m         \u001b[0;32mreturn\u001b[0m \u001b[0mDataFrameReader\u001b[0m\u001b[0;34m(\u001b[0m\u001b[0mself\u001b[0m\u001b[0;34m.\u001b[0m\u001b[0m_wrapped\u001b[0m\u001b[0;34m)\u001b[0m\u001b[0;34m\u001b[0m\u001b[0m\n\u001b[0m\u001b[1;32m    735\u001b[0m \u001b[0;34m\u001b[0m\u001b[0m\n\u001b[1;32m    736\u001b[0m     \u001b[0;34m@\u001b[0m\u001b[0mproperty\u001b[0m\u001b[0;34m\u001b[0m\u001b[0m\n",
      "\u001b[0;32m/home/hadoopuser/anaconda3/lib/python3.6/site-packages/pyspark/sql/readwriter.py\u001b[0m in \u001b[0;36m__init__\u001b[0;34m(self, spark)\u001b[0m\n\u001b[1;32m     68\u001b[0m \u001b[0;34m\u001b[0m\u001b[0m\n\u001b[1;32m     69\u001b[0m     \u001b[0;32mdef\u001b[0m \u001b[0m__init__\u001b[0m\u001b[0;34m(\u001b[0m\u001b[0mself\u001b[0m\u001b[0;34m,\u001b[0m \u001b[0mspark\u001b[0m\u001b[0;34m)\u001b[0m\u001b[0;34m:\u001b[0m\u001b[0;34m\u001b[0m\u001b[0m\n\u001b[0;32m---> 70\u001b[0;31m         \u001b[0mself\u001b[0m\u001b[0;34m.\u001b[0m\u001b[0m_jreader\u001b[0m \u001b[0;34m=\u001b[0m \u001b[0mspark\u001b[0m\u001b[0;34m.\u001b[0m\u001b[0m_ssql_ctx\u001b[0m\u001b[0;34m.\u001b[0m\u001b[0mread\u001b[0m\u001b[0;34m(\u001b[0m\u001b[0;34m)\u001b[0m\u001b[0;34m\u001b[0m\u001b[0m\n\u001b[0m\u001b[1;32m     71\u001b[0m         \u001b[0mself\u001b[0m\u001b[0;34m.\u001b[0m\u001b[0m_spark\u001b[0m \u001b[0;34m=\u001b[0m \u001b[0mspark\u001b[0m\u001b[0;34m\u001b[0m\u001b[0m\n\u001b[1;32m     72\u001b[0m \u001b[0;34m\u001b[0m\u001b[0m\n",
      "\u001b[0;32m/home/hadoopuser/anaconda3/lib/python3.6/site-packages/py4j/java_gateway.py\u001b[0m in \u001b[0;36m__call__\u001b[0;34m(self, *args)\u001b[0m\n\u001b[1;32m   1255\u001b[0m         \u001b[0manswer\u001b[0m \u001b[0;34m=\u001b[0m \u001b[0mself\u001b[0m\u001b[0;34m.\u001b[0m\u001b[0mgateway_client\u001b[0m\u001b[0;34m.\u001b[0m\u001b[0msend_command\u001b[0m\u001b[0;34m(\u001b[0m\u001b[0mcommand\u001b[0m\u001b[0;34m)\u001b[0m\u001b[0;34m\u001b[0m\u001b[0m\n\u001b[1;32m   1256\u001b[0m         return_value = get_return_value(\n\u001b[0;32m-> 1257\u001b[0;31m             answer, self.gateway_client, self.target_id, self.name)\n\u001b[0m\u001b[1;32m   1258\u001b[0m \u001b[0;34m\u001b[0m\u001b[0m\n\u001b[1;32m   1259\u001b[0m         \u001b[0;32mfor\u001b[0m \u001b[0mtemp_arg\u001b[0m \u001b[0;32min\u001b[0m \u001b[0mtemp_args\u001b[0m\u001b[0;34m:\u001b[0m\u001b[0;34m\u001b[0m\u001b[0m\n",
      "\u001b[0;32m/home/hadoopuser/anaconda3/lib/python3.6/site-packages/pyspark/sql/utils.py\u001b[0m in \u001b[0;36mdeco\u001b[0;34m(*a, **kw)\u001b[0m\n\u001b[1;32m     61\u001b[0m     \u001b[0;32mdef\u001b[0m \u001b[0mdeco\u001b[0m\u001b[0;34m(\u001b[0m\u001b[0;34m*\u001b[0m\u001b[0ma\u001b[0m\u001b[0;34m,\u001b[0m \u001b[0;34m**\u001b[0m\u001b[0mkw\u001b[0m\u001b[0;34m)\u001b[0m\u001b[0;34m:\u001b[0m\u001b[0;34m\u001b[0m\u001b[0m\n\u001b[1;32m     62\u001b[0m         \u001b[0;32mtry\u001b[0m\u001b[0;34m:\u001b[0m\u001b[0;34m\u001b[0m\u001b[0m\n\u001b[0;32m---> 63\u001b[0;31m             \u001b[0;32mreturn\u001b[0m \u001b[0mf\u001b[0m\u001b[0;34m(\u001b[0m\u001b[0;34m*\u001b[0m\u001b[0ma\u001b[0m\u001b[0;34m,\u001b[0m \u001b[0;34m**\u001b[0m\u001b[0mkw\u001b[0m\u001b[0;34m)\u001b[0m\u001b[0;34m\u001b[0m\u001b[0m\n\u001b[0m\u001b[1;32m     64\u001b[0m         \u001b[0;32mexcept\u001b[0m \u001b[0mpy4j\u001b[0m\u001b[0;34m.\u001b[0m\u001b[0mprotocol\u001b[0m\u001b[0;34m.\u001b[0m\u001b[0mPy4JJavaError\u001b[0m \u001b[0;32mas\u001b[0m \u001b[0me\u001b[0m\u001b[0;34m:\u001b[0m\u001b[0;34m\u001b[0m\u001b[0m\n\u001b[1;32m     65\u001b[0m             \u001b[0ms\u001b[0m \u001b[0;34m=\u001b[0m \u001b[0me\u001b[0m\u001b[0;34m.\u001b[0m\u001b[0mjava_exception\u001b[0m\u001b[0;34m.\u001b[0m\u001b[0mtoString\u001b[0m\u001b[0;34m(\u001b[0m\u001b[0;34m)\u001b[0m\u001b[0;34m\u001b[0m\u001b[0m\n",
      "\u001b[0;32m/home/hadoopuser/anaconda3/lib/python3.6/site-packages/py4j/protocol.py\u001b[0m in \u001b[0;36mget_return_value\u001b[0;34m(answer, gateway_client, target_id, name)\u001b[0m\n\u001b[1;32m    334\u001b[0m             raise Py4JError(\n\u001b[1;32m    335\u001b[0m                 \u001b[0;34m\"An error occurred while calling {0}{1}{2}\"\u001b[0m\u001b[0;34m.\u001b[0m\u001b[0;34m\u001b[0m\u001b[0m\n\u001b[0;32m--> 336\u001b[0;31m                 format(target_id, \".\", name))\n\u001b[0m\u001b[1;32m    337\u001b[0m     \u001b[0;32melse\u001b[0m\u001b[0;34m:\u001b[0m\u001b[0;34m\u001b[0m\u001b[0m\n\u001b[1;32m    338\u001b[0m         \u001b[0mtype\u001b[0m \u001b[0;34m=\u001b[0m \u001b[0manswer\u001b[0m\u001b[0;34m[\u001b[0m\u001b[0;36m1\u001b[0m\u001b[0;34m]\u001b[0m\u001b[0;34m\u001b[0m\u001b[0m\n",
      "\u001b[0;31mPy4JError\u001b[0m: An error occurred while calling o1015.read"
     ]
    },
    {
     "name": "stderr",
     "output_type": "stream",
     "text": [
      "ERROR:root:Exception while sending command.\n",
      "Traceback (most recent call last):\n",
      "  File \"/home/hadoopuser/anaconda3/lib/python3.6/site-packages/py4j/java_gateway.py\", line 1159, in send_command\n",
      "    raise Py4JNetworkError(\"Answer from Java side is empty\")\n",
      "py4j.protocol.Py4JNetworkError: Answer from Java side is empty\n",
      "\n",
      "During handling of the above exception, another exception occurred:\n",
      "\n",
      "Traceback (most recent call last):\n",
      "  File \"/home/hadoopuser/anaconda3/lib/python3.6/site-packages/py4j/java_gateway.py\", line 985, in send_command\n",
      "    response = connection.send_command(command)\n",
      "  File \"/home/hadoopuser/anaconda3/lib/python3.6/site-packages/py4j/java_gateway.py\", line 1164, in send_command\n",
      "    \"Error while receiving\", e, proto.ERROR_ON_RECEIVE)\n",
      "py4j.protocol.Py4JNetworkError: Error while receiving\n"
     ]
    }
   ],
   "source": [
    "dataframe2 = spark.read.format('csv').option('header','true').option('mode','DROPMALFORMED').load('input.txt')\n",
    "\n",
    "type(dataframe2)"
   ]
  },
  {
   "cell_type": "code",
   "execution_count": 76,
   "metadata": {},
   "outputs": [
    {
     "ename": "NameError",
     "evalue": "name 'dataframe2' is not defined",
     "output_type": "error",
     "traceback": [
      "\u001b[0;31m---------------------------------------------------------------------------\u001b[0m",
      "\u001b[0;31mNameError\u001b[0m                                 Traceback (most recent call last)",
      "\u001b[0;32m<ipython-input-76-d9c162748d1e>\u001b[0m in \u001b[0;36m<module>\u001b[0;34m()\u001b[0m\n\u001b[0;32m----> 1\u001b[0;31m \u001b[0mtype\u001b[0m\u001b[0;34m(\u001b[0m\u001b[0mdataframe2\u001b[0m\u001b[0;34m)\u001b[0m\u001b[0;34m\u001b[0m\u001b[0m\n\u001b[0m",
      "\u001b[0;31mNameError\u001b[0m: name 'dataframe2' is not defined"
     ]
    }
   ],
   "source": [
    "type(dataframe2)"
   ]
  },
  {
   "cell_type": "code",
   "execution_count": 77,
   "metadata": {},
   "outputs": [
    {
     "ename": "Py4JNetworkError",
     "evalue": "An error occurred while trying to connect to the Java server (127.0.0.1:42185)",
     "output_type": "error",
     "traceback": [
      "\u001b[0;31m---------------------------------------------------------------------------\u001b[0m",
      "\u001b[0;31mIndexError\u001b[0m                                Traceback (most recent call last)",
      "\u001b[0;32m/home/hadoopuser/anaconda3/lib/python3.6/site-packages/py4j/java_gateway.py\u001b[0m in \u001b[0;36m_get_connection\u001b[0;34m(self)\u001b[0m\n\u001b[1;32m    928\u001b[0m         \u001b[0;32mtry\u001b[0m\u001b[0;34m:\u001b[0m\u001b[0;34m\u001b[0m\u001b[0m\n\u001b[0;32m--> 929\u001b[0;31m             \u001b[0mconnection\u001b[0m \u001b[0;34m=\u001b[0m \u001b[0mself\u001b[0m\u001b[0;34m.\u001b[0m\u001b[0mdeque\u001b[0m\u001b[0;34m.\u001b[0m\u001b[0mpop\u001b[0m\u001b[0;34m(\u001b[0m\u001b[0;34m)\u001b[0m\u001b[0;34m\u001b[0m\u001b[0m\n\u001b[0m\u001b[1;32m    930\u001b[0m         \u001b[0;32mexcept\u001b[0m \u001b[0mIndexError\u001b[0m\u001b[0;34m:\u001b[0m\u001b[0;34m\u001b[0m\u001b[0m\n",
      "\u001b[0;31mIndexError\u001b[0m: pop from an empty deque",
      "\nDuring handling of the above exception, another exception occurred:\n",
      "\u001b[0;31mConnectionRefusedError\u001b[0m                    Traceback (most recent call last)",
      "\u001b[0;32m/home/hadoopuser/anaconda3/lib/python3.6/site-packages/py4j/java_gateway.py\u001b[0m in \u001b[0;36mstart\u001b[0;34m(self)\u001b[0m\n\u001b[1;32m   1066\u001b[0m         \u001b[0;32mtry\u001b[0m\u001b[0;34m:\u001b[0m\u001b[0;34m\u001b[0m\u001b[0m\n\u001b[0;32m-> 1067\u001b[0;31m             \u001b[0mself\u001b[0m\u001b[0;34m.\u001b[0m\u001b[0msocket\u001b[0m\u001b[0;34m.\u001b[0m\u001b[0mconnect\u001b[0m\u001b[0;34m(\u001b[0m\u001b[0;34m(\u001b[0m\u001b[0mself\u001b[0m\u001b[0;34m.\u001b[0m\u001b[0maddress\u001b[0m\u001b[0;34m,\u001b[0m \u001b[0mself\u001b[0m\u001b[0;34m.\u001b[0m\u001b[0mport\u001b[0m\u001b[0;34m)\u001b[0m\u001b[0;34m)\u001b[0m\u001b[0;34m\u001b[0m\u001b[0m\n\u001b[0m\u001b[1;32m   1068\u001b[0m             \u001b[0mself\u001b[0m\u001b[0;34m.\u001b[0m\u001b[0mstream\u001b[0m \u001b[0;34m=\u001b[0m \u001b[0mself\u001b[0m\u001b[0;34m.\u001b[0m\u001b[0msocket\u001b[0m\u001b[0;34m.\u001b[0m\u001b[0mmakefile\u001b[0m\u001b[0;34m(\u001b[0m\u001b[0;34m\"rb\"\u001b[0m\u001b[0;34m)\u001b[0m\u001b[0;34m\u001b[0m\u001b[0m\n",
      "\u001b[0;31mConnectionRefusedError\u001b[0m: [Errno 111] Connection refused",
      "\nDuring handling of the above exception, another exception occurred:\n",
      "\u001b[0;31mPy4JNetworkError\u001b[0m                          Traceback (most recent call last)",
      "\u001b[0;32m<ipython-input-77-36c66fd78926>\u001b[0m in \u001b[0;36m<module>\u001b[0;34m()\u001b[0m\n\u001b[0;32m----> 1\u001b[0;31m \u001b[0mspark\u001b[0m\u001b[0;34m.\u001b[0m\u001b[0msql\u001b[0m\u001b[0;34m(\u001b[0m\u001b[0;34m'create table movies          (movieId int,title string,genres string)          row format delimited fields terminated by \",\"         stored as textfile'\u001b[0m\u001b[0;34m)\u001b[0m                                              \u001b[0;31m# in textfile format\u001b[0m\u001b[0;34m\u001b[0m\u001b[0m\n\u001b[0m\u001b[1;32m      2\u001b[0m \u001b[0mspark\u001b[0m\u001b[0;34m.\u001b[0m\u001b[0msql\u001b[0m\u001b[0;34m(\u001b[0m\u001b[0;34m\"create table ratings           (userId int,movieId int,rating float,timestamp string)           stored as ORC\"\u001b[0m \u001b[0;34m)\u001b[0m\u001b[0;34m\u001b[0m\u001b[0m\n",
      "\u001b[0;32m/home/hadoopuser/anaconda3/lib/python3.6/site-packages/pyspark/sql/session.py\u001b[0m in \u001b[0;36msql\u001b[0;34m(self, sqlQuery)\u001b[0m\n\u001b[1;32m    708\u001b[0m         \u001b[0;34m[\u001b[0m\u001b[0mRow\u001b[0m\u001b[0;34m(\u001b[0m\u001b[0mf1\u001b[0m\u001b[0;34m=\u001b[0m\u001b[0;36m1\u001b[0m\u001b[0;34m,\u001b[0m \u001b[0mf2\u001b[0m\u001b[0;34m=\u001b[0m\u001b[0;34mu'row1'\u001b[0m\u001b[0;34m)\u001b[0m\u001b[0;34m,\u001b[0m \u001b[0mRow\u001b[0m\u001b[0;34m(\u001b[0m\u001b[0mf1\u001b[0m\u001b[0;34m=\u001b[0m\u001b[0;36m2\u001b[0m\u001b[0;34m,\u001b[0m \u001b[0mf2\u001b[0m\u001b[0;34m=\u001b[0m\u001b[0;34mu'row2'\u001b[0m\u001b[0;34m)\u001b[0m\u001b[0;34m,\u001b[0m \u001b[0mRow\u001b[0m\u001b[0;34m(\u001b[0m\u001b[0mf1\u001b[0m\u001b[0;34m=\u001b[0m\u001b[0;36m3\u001b[0m\u001b[0;34m,\u001b[0m \u001b[0mf2\u001b[0m\u001b[0;34m=\u001b[0m\u001b[0;34mu'row3'\u001b[0m\u001b[0;34m)\u001b[0m\u001b[0;34m]\u001b[0m\u001b[0;34m\u001b[0m\u001b[0m\n\u001b[1;32m    709\u001b[0m         \"\"\"\n\u001b[0;32m--> 710\u001b[0;31m         \u001b[0;32mreturn\u001b[0m \u001b[0mDataFrame\u001b[0m\u001b[0;34m(\u001b[0m\u001b[0mself\u001b[0m\u001b[0;34m.\u001b[0m\u001b[0m_jsparkSession\u001b[0m\u001b[0;34m.\u001b[0m\u001b[0msql\u001b[0m\u001b[0;34m(\u001b[0m\u001b[0msqlQuery\u001b[0m\u001b[0;34m)\u001b[0m\u001b[0;34m,\u001b[0m \u001b[0mself\u001b[0m\u001b[0;34m.\u001b[0m\u001b[0m_wrapped\u001b[0m\u001b[0;34m)\u001b[0m\u001b[0;34m\u001b[0m\u001b[0m\n\u001b[0m\u001b[1;32m    711\u001b[0m \u001b[0;34m\u001b[0m\u001b[0m\n\u001b[1;32m    712\u001b[0m     \u001b[0;34m@\u001b[0m\u001b[0msince\u001b[0m\u001b[0;34m(\u001b[0m\u001b[0;36m2.0\u001b[0m\u001b[0;34m)\u001b[0m\u001b[0;34m\u001b[0m\u001b[0m\n",
      "\u001b[0;32m/home/hadoopuser/anaconda3/lib/python3.6/site-packages/py4j/java_gateway.py\u001b[0m in \u001b[0;36m__call__\u001b[0;34m(self, *args)\u001b[0m\n\u001b[1;32m   1253\u001b[0m             \u001b[0mproto\u001b[0m\u001b[0;34m.\u001b[0m\u001b[0mEND_COMMAND_PART\u001b[0m\u001b[0;34m\u001b[0m\u001b[0m\n\u001b[1;32m   1254\u001b[0m \u001b[0;34m\u001b[0m\u001b[0m\n\u001b[0;32m-> 1255\u001b[0;31m         \u001b[0manswer\u001b[0m \u001b[0;34m=\u001b[0m \u001b[0mself\u001b[0m\u001b[0;34m.\u001b[0m\u001b[0mgateway_client\u001b[0m\u001b[0;34m.\u001b[0m\u001b[0msend_command\u001b[0m\u001b[0;34m(\u001b[0m\u001b[0mcommand\u001b[0m\u001b[0;34m)\u001b[0m\u001b[0;34m\u001b[0m\u001b[0m\n\u001b[0m\u001b[1;32m   1256\u001b[0m         return_value = get_return_value(\n\u001b[1;32m   1257\u001b[0m             answer, self.gateway_client, self.target_id, self.name)\n",
      "\u001b[0;32m/home/hadoopuser/anaconda3/lib/python3.6/site-packages/py4j/java_gateway.py\u001b[0m in \u001b[0;36msend_command\u001b[0;34m(self, command, retry, binary)\u001b[0m\n\u001b[1;32m    981\u001b[0m          \u001b[0;32mif\u001b[0m\u001b[0;31m \u001b[0m\u001b[0;31m`\u001b[0m\u001b[0mbinary\u001b[0m\u001b[0;31m`\u001b[0m \u001b[0;32mis\u001b[0m\u001b[0;31m \u001b[0m\u001b[0;31m`\u001b[0m\u001b[0;32mTrue\u001b[0m\u001b[0;31m`\u001b[0m\u001b[0;34m.\u001b[0m\u001b[0;34m\u001b[0m\u001b[0m\n\u001b[1;32m    982\u001b[0m         \"\"\"\n\u001b[0;32m--> 983\u001b[0;31m         \u001b[0mconnection\u001b[0m \u001b[0;34m=\u001b[0m \u001b[0mself\u001b[0m\u001b[0;34m.\u001b[0m\u001b[0m_get_connection\u001b[0m\u001b[0;34m(\u001b[0m\u001b[0;34m)\u001b[0m\u001b[0;34m\u001b[0m\u001b[0m\n\u001b[0m\u001b[1;32m    984\u001b[0m         \u001b[0;32mtry\u001b[0m\u001b[0;34m:\u001b[0m\u001b[0;34m\u001b[0m\u001b[0m\n\u001b[1;32m    985\u001b[0m             \u001b[0mresponse\u001b[0m \u001b[0;34m=\u001b[0m \u001b[0mconnection\u001b[0m\u001b[0;34m.\u001b[0m\u001b[0msend_command\u001b[0m\u001b[0;34m(\u001b[0m\u001b[0mcommand\u001b[0m\u001b[0;34m)\u001b[0m\u001b[0;34m\u001b[0m\u001b[0m\n",
      "\u001b[0;32m/home/hadoopuser/anaconda3/lib/python3.6/site-packages/py4j/java_gateway.py\u001b[0m in \u001b[0;36m_get_connection\u001b[0;34m(self)\u001b[0m\n\u001b[1;32m    929\u001b[0m             \u001b[0mconnection\u001b[0m \u001b[0;34m=\u001b[0m \u001b[0mself\u001b[0m\u001b[0;34m.\u001b[0m\u001b[0mdeque\u001b[0m\u001b[0;34m.\u001b[0m\u001b[0mpop\u001b[0m\u001b[0;34m(\u001b[0m\u001b[0;34m)\u001b[0m\u001b[0;34m\u001b[0m\u001b[0m\n\u001b[1;32m    930\u001b[0m         \u001b[0;32mexcept\u001b[0m \u001b[0mIndexError\u001b[0m\u001b[0;34m:\u001b[0m\u001b[0;34m\u001b[0m\u001b[0m\n\u001b[0;32m--> 931\u001b[0;31m             \u001b[0mconnection\u001b[0m \u001b[0;34m=\u001b[0m \u001b[0mself\u001b[0m\u001b[0;34m.\u001b[0m\u001b[0m_create_connection\u001b[0m\u001b[0;34m(\u001b[0m\u001b[0;34m)\u001b[0m\u001b[0;34m\u001b[0m\u001b[0m\n\u001b[0m\u001b[1;32m    932\u001b[0m         \u001b[0;32mreturn\u001b[0m \u001b[0mconnection\u001b[0m\u001b[0;34m\u001b[0m\u001b[0m\n\u001b[1;32m    933\u001b[0m \u001b[0;34m\u001b[0m\u001b[0m\n",
      "\u001b[0;32m/home/hadoopuser/anaconda3/lib/python3.6/site-packages/py4j/java_gateway.py\u001b[0m in \u001b[0;36m_create_connection\u001b[0;34m(self)\u001b[0m\n\u001b[1;32m    935\u001b[0m         connection = GatewayConnection(\n\u001b[1;32m    936\u001b[0m             self.gateway_parameters, self.gateway_property)\n\u001b[0;32m--> 937\u001b[0;31m         \u001b[0mconnection\u001b[0m\u001b[0;34m.\u001b[0m\u001b[0mstart\u001b[0m\u001b[0;34m(\u001b[0m\u001b[0;34m)\u001b[0m\u001b[0;34m\u001b[0m\u001b[0m\n\u001b[0m\u001b[1;32m    938\u001b[0m         \u001b[0;32mreturn\u001b[0m \u001b[0mconnection\u001b[0m\u001b[0;34m\u001b[0m\u001b[0m\n\u001b[1;32m    939\u001b[0m \u001b[0;34m\u001b[0m\u001b[0m\n",
      "\u001b[0;32m/home/hadoopuser/anaconda3/lib/python3.6/site-packages/py4j/java_gateway.py\u001b[0m in \u001b[0;36mstart\u001b[0;34m(self)\u001b[0m\n\u001b[1;32m   1077\u001b[0m                 \u001b[0;34m\"server ({0}:{1})\"\u001b[0m\u001b[0;34m.\u001b[0m\u001b[0mformat\u001b[0m\u001b[0;34m(\u001b[0m\u001b[0mself\u001b[0m\u001b[0;34m.\u001b[0m\u001b[0maddress\u001b[0m\u001b[0;34m,\u001b[0m \u001b[0mself\u001b[0m\u001b[0;34m.\u001b[0m\u001b[0mport\u001b[0m\u001b[0;34m)\u001b[0m\u001b[0;34m\u001b[0m\u001b[0m\n\u001b[1;32m   1078\u001b[0m             \u001b[0mlogger\u001b[0m\u001b[0;34m.\u001b[0m\u001b[0mexception\u001b[0m\u001b[0;34m(\u001b[0m\u001b[0mmsg\u001b[0m\u001b[0;34m)\u001b[0m\u001b[0;34m\u001b[0m\u001b[0m\n\u001b[0;32m-> 1079\u001b[0;31m             \u001b[0;32mraise\u001b[0m \u001b[0mPy4JNetworkError\u001b[0m\u001b[0;34m(\u001b[0m\u001b[0mmsg\u001b[0m\u001b[0;34m,\u001b[0m \u001b[0me\u001b[0m\u001b[0;34m)\u001b[0m\u001b[0;34m\u001b[0m\u001b[0m\n\u001b[0m\u001b[1;32m   1080\u001b[0m \u001b[0;34m\u001b[0m\u001b[0m\n\u001b[1;32m   1081\u001b[0m     \u001b[0;32mdef\u001b[0m \u001b[0m_authenticate_connection\u001b[0m\u001b[0;34m(\u001b[0m\u001b[0mself\u001b[0m\u001b[0;34m)\u001b[0m\u001b[0;34m:\u001b[0m\u001b[0;34m\u001b[0m\u001b[0m\n",
      "\u001b[0;31mPy4JNetworkError\u001b[0m: An error occurred while trying to connect to the Java server (127.0.0.1:42185)"
     ]
    }
   ],
   "source": [
    "spark.sql('create table movies \\\n",
    "         (movieId int,title string,genres string) \\\n",
    "         row format delimited fields terminated by \",\"\\\n",
    "         stored as textfile')                                              # in textfile format\n",
    "spark.sql(\"create table ratings\\\n",
    "           (userId int,movieId int,rating float,timestamp string)\\\n",
    "           stored as ORC\" )       "
   ]
  },
  {
   "cell_type": "code",
   "execution_count": 78,
   "metadata": {},
   "outputs": [
    {
     "ename": "Py4JNetworkError",
     "evalue": "An error occurred while trying to connect to the Java server (127.0.0.1:42185)",
     "output_type": "error",
     "traceback": [
      "\u001b[0;31m---------------------------------------------------------------------------\u001b[0m",
      "\u001b[0;31mIndexError\u001b[0m                                Traceback (most recent call last)",
      "\u001b[0;32m/home/hadoopuser/anaconda3/lib/python3.6/site-packages/py4j/java_gateway.py\u001b[0m in \u001b[0;36m_get_connection\u001b[0;34m(self)\u001b[0m\n\u001b[1;32m    928\u001b[0m         \u001b[0;32mtry\u001b[0m\u001b[0;34m:\u001b[0m\u001b[0;34m\u001b[0m\u001b[0m\n\u001b[0;32m--> 929\u001b[0;31m             \u001b[0mconnection\u001b[0m \u001b[0;34m=\u001b[0m \u001b[0mself\u001b[0m\u001b[0;34m.\u001b[0m\u001b[0mdeque\u001b[0m\u001b[0;34m.\u001b[0m\u001b[0mpop\u001b[0m\u001b[0;34m(\u001b[0m\u001b[0;34m)\u001b[0m\u001b[0;34m\u001b[0m\u001b[0m\n\u001b[0m\u001b[1;32m    930\u001b[0m         \u001b[0;32mexcept\u001b[0m \u001b[0mIndexError\u001b[0m\u001b[0;34m:\u001b[0m\u001b[0;34m\u001b[0m\u001b[0m\n",
      "\u001b[0;31mIndexError\u001b[0m: pop from an empty deque",
      "\nDuring handling of the above exception, another exception occurred:\n",
      "\u001b[0;31mConnectionRefusedError\u001b[0m                    Traceback (most recent call last)",
      "\u001b[0;32m/home/hadoopuser/anaconda3/lib/python3.6/site-packages/py4j/java_gateway.py\u001b[0m in \u001b[0;36mstart\u001b[0;34m(self)\u001b[0m\n\u001b[1;32m   1066\u001b[0m         \u001b[0;32mtry\u001b[0m\u001b[0;34m:\u001b[0m\u001b[0;34m\u001b[0m\u001b[0m\n\u001b[0;32m-> 1067\u001b[0;31m             \u001b[0mself\u001b[0m\u001b[0;34m.\u001b[0m\u001b[0msocket\u001b[0m\u001b[0;34m.\u001b[0m\u001b[0mconnect\u001b[0m\u001b[0;34m(\u001b[0m\u001b[0;34m(\u001b[0m\u001b[0mself\u001b[0m\u001b[0;34m.\u001b[0m\u001b[0maddress\u001b[0m\u001b[0;34m,\u001b[0m \u001b[0mself\u001b[0m\u001b[0;34m.\u001b[0m\u001b[0mport\u001b[0m\u001b[0;34m)\u001b[0m\u001b[0;34m)\u001b[0m\u001b[0;34m\u001b[0m\u001b[0m\n\u001b[0m\u001b[1;32m   1068\u001b[0m             \u001b[0mself\u001b[0m\u001b[0;34m.\u001b[0m\u001b[0mstream\u001b[0m \u001b[0;34m=\u001b[0m \u001b[0mself\u001b[0m\u001b[0;34m.\u001b[0m\u001b[0msocket\u001b[0m\u001b[0;34m.\u001b[0m\u001b[0mmakefile\u001b[0m\u001b[0;34m(\u001b[0m\u001b[0;34m\"rb\"\u001b[0m\u001b[0;34m)\u001b[0m\u001b[0;34m\u001b[0m\u001b[0m\n",
      "\u001b[0;31mConnectionRefusedError\u001b[0m: [Errno 111] Connection refused",
      "\nDuring handling of the above exception, another exception occurred:\n",
      "\u001b[0;31mPy4JNetworkError\u001b[0m                          Traceback (most recent call last)",
      "\u001b[0;32m<ipython-input-78-ad9d562dc20d>\u001b[0m in \u001b[0;36m<module>\u001b[0;34m()\u001b[0m\n\u001b[0;32m----> 1\u001b[0;31m \u001b[0mspark\u001b[0m\u001b[0;34m.\u001b[0m\u001b[0msql\u001b[0m\u001b[0;34m(\u001b[0m\u001b[0;34m'select * from movies'\u001b[0m\u001b[0;34m)\u001b[0m\u001b[0;34m\u001b[0m\u001b[0m\n\u001b[0m",
      "\u001b[0;32m/home/hadoopuser/anaconda3/lib/python3.6/site-packages/pyspark/sql/session.py\u001b[0m in \u001b[0;36msql\u001b[0;34m(self, sqlQuery)\u001b[0m\n\u001b[1;32m    708\u001b[0m         \u001b[0;34m[\u001b[0m\u001b[0mRow\u001b[0m\u001b[0;34m(\u001b[0m\u001b[0mf1\u001b[0m\u001b[0;34m=\u001b[0m\u001b[0;36m1\u001b[0m\u001b[0;34m,\u001b[0m \u001b[0mf2\u001b[0m\u001b[0;34m=\u001b[0m\u001b[0;34mu'row1'\u001b[0m\u001b[0;34m)\u001b[0m\u001b[0;34m,\u001b[0m \u001b[0mRow\u001b[0m\u001b[0;34m(\u001b[0m\u001b[0mf1\u001b[0m\u001b[0;34m=\u001b[0m\u001b[0;36m2\u001b[0m\u001b[0;34m,\u001b[0m \u001b[0mf2\u001b[0m\u001b[0;34m=\u001b[0m\u001b[0;34mu'row2'\u001b[0m\u001b[0;34m)\u001b[0m\u001b[0;34m,\u001b[0m \u001b[0mRow\u001b[0m\u001b[0;34m(\u001b[0m\u001b[0mf1\u001b[0m\u001b[0;34m=\u001b[0m\u001b[0;36m3\u001b[0m\u001b[0;34m,\u001b[0m \u001b[0mf2\u001b[0m\u001b[0;34m=\u001b[0m\u001b[0;34mu'row3'\u001b[0m\u001b[0;34m)\u001b[0m\u001b[0;34m]\u001b[0m\u001b[0;34m\u001b[0m\u001b[0m\n\u001b[1;32m    709\u001b[0m         \"\"\"\n\u001b[0;32m--> 710\u001b[0;31m         \u001b[0;32mreturn\u001b[0m \u001b[0mDataFrame\u001b[0m\u001b[0;34m(\u001b[0m\u001b[0mself\u001b[0m\u001b[0;34m.\u001b[0m\u001b[0m_jsparkSession\u001b[0m\u001b[0;34m.\u001b[0m\u001b[0msql\u001b[0m\u001b[0;34m(\u001b[0m\u001b[0msqlQuery\u001b[0m\u001b[0;34m)\u001b[0m\u001b[0;34m,\u001b[0m \u001b[0mself\u001b[0m\u001b[0;34m.\u001b[0m\u001b[0m_wrapped\u001b[0m\u001b[0;34m)\u001b[0m\u001b[0;34m\u001b[0m\u001b[0m\n\u001b[0m\u001b[1;32m    711\u001b[0m \u001b[0;34m\u001b[0m\u001b[0m\n\u001b[1;32m    712\u001b[0m     \u001b[0;34m@\u001b[0m\u001b[0msince\u001b[0m\u001b[0;34m(\u001b[0m\u001b[0;36m2.0\u001b[0m\u001b[0;34m)\u001b[0m\u001b[0;34m\u001b[0m\u001b[0m\n",
      "\u001b[0;32m/home/hadoopuser/anaconda3/lib/python3.6/site-packages/py4j/java_gateway.py\u001b[0m in \u001b[0;36m__call__\u001b[0;34m(self, *args)\u001b[0m\n\u001b[1;32m   1253\u001b[0m             \u001b[0mproto\u001b[0m\u001b[0;34m.\u001b[0m\u001b[0mEND_COMMAND_PART\u001b[0m\u001b[0;34m\u001b[0m\u001b[0m\n\u001b[1;32m   1254\u001b[0m \u001b[0;34m\u001b[0m\u001b[0m\n\u001b[0;32m-> 1255\u001b[0;31m         \u001b[0manswer\u001b[0m \u001b[0;34m=\u001b[0m \u001b[0mself\u001b[0m\u001b[0;34m.\u001b[0m\u001b[0mgateway_client\u001b[0m\u001b[0;34m.\u001b[0m\u001b[0msend_command\u001b[0m\u001b[0;34m(\u001b[0m\u001b[0mcommand\u001b[0m\u001b[0;34m)\u001b[0m\u001b[0;34m\u001b[0m\u001b[0m\n\u001b[0m\u001b[1;32m   1256\u001b[0m         return_value = get_return_value(\n\u001b[1;32m   1257\u001b[0m             answer, self.gateway_client, self.target_id, self.name)\n",
      "\u001b[0;32m/home/hadoopuser/anaconda3/lib/python3.6/site-packages/py4j/java_gateway.py\u001b[0m in \u001b[0;36msend_command\u001b[0;34m(self, command, retry, binary)\u001b[0m\n\u001b[1;32m    981\u001b[0m          \u001b[0;32mif\u001b[0m\u001b[0;31m \u001b[0m\u001b[0;31m`\u001b[0m\u001b[0mbinary\u001b[0m\u001b[0;31m`\u001b[0m \u001b[0;32mis\u001b[0m\u001b[0;31m \u001b[0m\u001b[0;31m`\u001b[0m\u001b[0;32mTrue\u001b[0m\u001b[0;31m`\u001b[0m\u001b[0;34m.\u001b[0m\u001b[0;34m\u001b[0m\u001b[0m\n\u001b[1;32m    982\u001b[0m         \"\"\"\n\u001b[0;32m--> 983\u001b[0;31m         \u001b[0mconnection\u001b[0m \u001b[0;34m=\u001b[0m \u001b[0mself\u001b[0m\u001b[0;34m.\u001b[0m\u001b[0m_get_connection\u001b[0m\u001b[0;34m(\u001b[0m\u001b[0;34m)\u001b[0m\u001b[0;34m\u001b[0m\u001b[0m\n\u001b[0m\u001b[1;32m    984\u001b[0m         \u001b[0;32mtry\u001b[0m\u001b[0;34m:\u001b[0m\u001b[0;34m\u001b[0m\u001b[0m\n\u001b[1;32m    985\u001b[0m             \u001b[0mresponse\u001b[0m \u001b[0;34m=\u001b[0m \u001b[0mconnection\u001b[0m\u001b[0;34m.\u001b[0m\u001b[0msend_command\u001b[0m\u001b[0;34m(\u001b[0m\u001b[0mcommand\u001b[0m\u001b[0;34m)\u001b[0m\u001b[0;34m\u001b[0m\u001b[0m\n",
      "\u001b[0;32m/home/hadoopuser/anaconda3/lib/python3.6/site-packages/py4j/java_gateway.py\u001b[0m in \u001b[0;36m_get_connection\u001b[0;34m(self)\u001b[0m\n\u001b[1;32m    929\u001b[0m             \u001b[0mconnection\u001b[0m \u001b[0;34m=\u001b[0m \u001b[0mself\u001b[0m\u001b[0;34m.\u001b[0m\u001b[0mdeque\u001b[0m\u001b[0;34m.\u001b[0m\u001b[0mpop\u001b[0m\u001b[0;34m(\u001b[0m\u001b[0;34m)\u001b[0m\u001b[0;34m\u001b[0m\u001b[0m\n\u001b[1;32m    930\u001b[0m         \u001b[0;32mexcept\u001b[0m \u001b[0mIndexError\u001b[0m\u001b[0;34m:\u001b[0m\u001b[0;34m\u001b[0m\u001b[0m\n\u001b[0;32m--> 931\u001b[0;31m             \u001b[0mconnection\u001b[0m \u001b[0;34m=\u001b[0m \u001b[0mself\u001b[0m\u001b[0;34m.\u001b[0m\u001b[0m_create_connection\u001b[0m\u001b[0;34m(\u001b[0m\u001b[0;34m)\u001b[0m\u001b[0;34m\u001b[0m\u001b[0m\n\u001b[0m\u001b[1;32m    932\u001b[0m         \u001b[0;32mreturn\u001b[0m \u001b[0mconnection\u001b[0m\u001b[0;34m\u001b[0m\u001b[0m\n\u001b[1;32m    933\u001b[0m \u001b[0;34m\u001b[0m\u001b[0m\n",
      "\u001b[0;32m/home/hadoopuser/anaconda3/lib/python3.6/site-packages/py4j/java_gateway.py\u001b[0m in \u001b[0;36m_create_connection\u001b[0;34m(self)\u001b[0m\n\u001b[1;32m    935\u001b[0m         connection = GatewayConnection(\n\u001b[1;32m    936\u001b[0m             self.gateway_parameters, self.gateway_property)\n\u001b[0;32m--> 937\u001b[0;31m         \u001b[0mconnection\u001b[0m\u001b[0;34m.\u001b[0m\u001b[0mstart\u001b[0m\u001b[0;34m(\u001b[0m\u001b[0;34m)\u001b[0m\u001b[0;34m\u001b[0m\u001b[0m\n\u001b[0m\u001b[1;32m    938\u001b[0m         \u001b[0;32mreturn\u001b[0m \u001b[0mconnection\u001b[0m\u001b[0;34m\u001b[0m\u001b[0m\n\u001b[1;32m    939\u001b[0m \u001b[0;34m\u001b[0m\u001b[0m\n",
      "\u001b[0;32m/home/hadoopuser/anaconda3/lib/python3.6/site-packages/py4j/java_gateway.py\u001b[0m in \u001b[0;36mstart\u001b[0;34m(self)\u001b[0m\n\u001b[1;32m   1077\u001b[0m                 \u001b[0;34m\"server ({0}:{1})\"\u001b[0m\u001b[0;34m.\u001b[0m\u001b[0mformat\u001b[0m\u001b[0;34m(\u001b[0m\u001b[0mself\u001b[0m\u001b[0;34m.\u001b[0m\u001b[0maddress\u001b[0m\u001b[0;34m,\u001b[0m \u001b[0mself\u001b[0m\u001b[0;34m.\u001b[0m\u001b[0mport\u001b[0m\u001b[0;34m)\u001b[0m\u001b[0;34m\u001b[0m\u001b[0m\n\u001b[1;32m   1078\u001b[0m             \u001b[0mlogger\u001b[0m\u001b[0;34m.\u001b[0m\u001b[0mexception\u001b[0m\u001b[0;34m(\u001b[0m\u001b[0mmsg\u001b[0m\u001b[0;34m)\u001b[0m\u001b[0;34m\u001b[0m\u001b[0m\n\u001b[0;32m-> 1079\u001b[0;31m             \u001b[0;32mraise\u001b[0m \u001b[0mPy4JNetworkError\u001b[0m\u001b[0;34m(\u001b[0m\u001b[0mmsg\u001b[0m\u001b[0;34m,\u001b[0m \u001b[0me\u001b[0m\u001b[0;34m)\u001b[0m\u001b[0;34m\u001b[0m\u001b[0m\n\u001b[0m\u001b[1;32m   1080\u001b[0m \u001b[0;34m\u001b[0m\u001b[0m\n\u001b[1;32m   1081\u001b[0m     \u001b[0;32mdef\u001b[0m \u001b[0m_authenticate_connection\u001b[0m\u001b[0;34m(\u001b[0m\u001b[0mself\u001b[0m\u001b[0;34m)\u001b[0m\u001b[0;34m:\u001b[0m\u001b[0;34m\u001b[0m\u001b[0m\n",
      "\u001b[0;31mPy4JNetworkError\u001b[0m: An error occurred while trying to connect to the Java server (127.0.0.1:42185)"
     ]
    }
   ],
   "source": [
    "spark.sql('select * from movies')"
   ]
  },
  {
   "cell_type": "code",
   "execution_count": 79,
   "metadata": {},
   "outputs": [
    {
     "ename": "NameError",
     "evalue": "name 'dataframe2' is not defined",
     "output_type": "error",
     "traceback": [
      "\u001b[0;31m---------------------------------------------------------------------------\u001b[0m",
      "\u001b[0;31mNameError\u001b[0m                                 Traceback (most recent call last)",
      "\u001b[0;32m<ipython-input-79-4ad92ae77b04>\u001b[0m in \u001b[0;36m<module>\u001b[0;34m()\u001b[0m\n\u001b[0;32m----> 1\u001b[0;31m \u001b[0mdataframe2\u001b[0m\u001b[0;34m\u001b[0m\u001b[0m\n\u001b[0m",
      "\u001b[0;31mNameError\u001b[0m: name 'dataframe2' is not defined"
     ]
    }
   ],
   "source": [
    "dataframe2"
   ]
  },
  {
   "cell_type": "code",
   "execution_count": 80,
   "metadata": {},
   "outputs": [
    {
     "ename": "SyntaxError",
     "evalue": "invalid syntax (<ipython-input-80-591db63aac50>, line 1)",
     "output_type": "error",
     "traceback": [
      "\u001b[0;36m  File \u001b[0;32m\"<ipython-input-80-591db63aac50>\"\u001b[0;36m, line \u001b[0;32m1\u001b[0m\n\u001b[0;31m    df = sqlContext.read.format('input.csv').options(header='true').\u001b[0m\n\u001b[0m                                                                    ^\u001b[0m\n\u001b[0;31mSyntaxError\u001b[0m\u001b[0;31m:\u001b[0m invalid syntax\n"
     ]
    }
   ],
   "source": [
    "df = sqlContext.read.format('input.csv').options(header='true')."
   ]
  },
  {
   "cell_type": "code",
   "execution_count": 81,
   "metadata": {},
   "outputs": [
    {
     "data": {
      "text/plain": [
       "DataFrame[user_id: bigint, genre_id: bigint]"
      ]
     },
     "execution_count": 81,
     "metadata": {},
     "output_type": "execute_result"
    },
    {
     "name": "stderr",
     "output_type": "stream",
     "text": [
      "ERROR:root:Exception while sending command.\n",
      "Traceback (most recent call last):\n",
      "  File \"/home/hadoopuser/anaconda3/lib/python3.6/site-packages/py4j/java_gateway.py\", line 1159, in send_command\n",
      "    raise Py4JNetworkError(\"Answer from Java side is empty\")\n",
      "py4j.protocol.Py4JNetworkError: Answer from Java side is empty\n",
      "\n",
      "During handling of the above exception, another exception occurred:\n",
      "\n",
      "Traceback (most recent call last):\n",
      "  File \"/home/hadoopuser/anaconda3/lib/python3.6/site-packages/py4j/java_gateway.py\", line 985, in send_command\n",
      "    response = connection.send_command(command)\n",
      "  File \"/home/hadoopuser/anaconda3/lib/python3.6/site-packages/py4j/java_gateway.py\", line 1164, in send_command\n",
      "    \"Error while receiving\", e, proto.ERROR_ON_RECEIVE)\n",
      "py4j.protocol.Py4JNetworkError: Error while receiving\n",
      "ERROR:py4j.java_gateway:An error occurred while trying to connect to the Java server (127.0.0.1:42185)\n",
      "Traceback (most recent call last):\n",
      "  File \"/home/hadoopuser/anaconda3/lib/python3.6/site-packages/py4j/java_gateway.py\", line 929, in _get_connection\n",
      "    connection = self.deque.pop()\n",
      "IndexError: pop from an empty deque\n",
      "\n",
      "During handling of the above exception, another exception occurred:\n",
      "\n",
      "Traceback (most recent call last):\n",
      "  File \"/home/hadoopuser/anaconda3/lib/python3.6/site-packages/py4j/java_gateway.py\", line 1067, in start\n",
      "    self.socket.connect((self.address, self.port))\n",
      "ConnectionRefusedError: [Errno 111] Connection refused\n",
      "ERROR:py4j.java_gateway:An error occurred while trying to connect to the Java server (127.0.0.1:42185)\n",
      "Traceback (most recent call last):\n",
      "  File \"/home/hadoopuser/anaconda3/lib/python3.6/site-packages/py4j/java_gateway.py\", line 929, in _get_connection\n",
      "    connection = self.deque.pop()\n",
      "IndexError: pop from an empty deque\n",
      "\n",
      "During handling of the above exception, another exception occurred:\n",
      "\n",
      "Traceback (most recent call last):\n",
      "  File \"/home/hadoopuser/anaconda3/lib/python3.6/site-packages/py4j/java_gateway.py\", line 1067, in start\n",
      "    self.socket.connect((self.address, self.port))\n",
      "ConnectionRefusedError: [Errno 111] Connection refused\n",
      "ERROR:py4j.java_gateway:An error occurred while trying to connect to the Java server (127.0.0.1:42185)\n",
      "Traceback (most recent call last):\n",
      "  File \"/home/hadoopuser/anaconda3/lib/python3.6/site-packages/py4j/java_gateway.py\", line 929, in _get_connection\n",
      "    connection = self.deque.pop()\n",
      "IndexError: pop from an empty deque\n",
      "\n",
      "During handling of the above exception, another exception occurred:\n",
      "\n",
      "Traceback (most recent call last):\n",
      "  File \"/home/hadoopuser/anaconda3/lib/python3.6/site-packages/py4j/java_gateway.py\", line 1067, in start\n",
      "    self.socket.connect((self.address, self.port))\n",
      "ConnectionRefusedError: [Errno 111] Connection refused\n",
      "ERROR:py4j.java_gateway:An error occurred while trying to connect to the Java server (127.0.0.1:42185)\n",
      "Traceback (most recent call last):\n",
      "  File \"/home/hadoopuser/anaconda3/lib/python3.6/site-packages/py4j/java_gateway.py\", line 929, in _get_connection\n",
      "    connection = self.deque.pop()\n",
      "IndexError: pop from an empty deque\n",
      "\n",
      "During handling of the above exception, another exception occurred:\n",
      "\n",
      "Traceback (most recent call last):\n",
      "  File \"/home/hadoopuser/anaconda3/lib/python3.6/site-packages/py4j/java_gateway.py\", line 1067, in start\n",
      "    self.socket.connect((self.address, self.port))\n",
      "ConnectionRefusedError: [Errno 111] Connection refused\n",
      "ERROR:py4j.java_gateway:An error occurred while trying to connect to the Java server (127.0.0.1:42185)\n",
      "Traceback (most recent call last):\n",
      "  File \"/home/hadoopuser/anaconda3/lib/python3.6/site-packages/py4j/java_gateway.py\", line 929, in _get_connection\n",
      "    connection = self.deque.pop()\n",
      "IndexError: pop from an empty deque\n",
      "\n",
      "During handling of the above exception, another exception occurred:\n",
      "\n",
      "Traceback (most recent call last):\n",
      "  File \"/home/hadoopuser/anaconda3/lib/python3.6/site-packages/py4j/java_gateway.py\", line 1067, in start\n",
      "    self.socket.connect((self.address, self.port))\n",
      "ConnectionRefusedError: [Errno 111] Connection refused\n",
      "ERROR:py4j.java_gateway:An error occurred while trying to connect to the Java server (127.0.0.1:42185)\n",
      "Traceback (most recent call last):\n",
      "  File \"/home/hadoopuser/anaconda3/lib/python3.6/site-packages/py4j/java_gateway.py\", line 929, in _get_connection\n",
      "    connection = self.deque.pop()\n",
      "IndexError: pop from an empty deque\n",
      "\n",
      "During handling of the above exception, another exception occurred:\n",
      "\n",
      "Traceback (most recent call last):\n",
      "  File \"/home/hadoopuser/anaconda3/lib/python3.6/site-packages/py4j/java_gateway.py\", line 1067, in start\n",
      "    self.socket.connect((self.address, self.port))\n",
      "ConnectionRefusedError: [Errno 111] Connection refused\n",
      "ERROR:py4j.java_gateway:An error occurred while trying to connect to the Java server (127.0.0.1:42185)\n",
      "Traceback (most recent call last):\n",
      "  File \"/home/hadoopuser/anaconda3/lib/python3.6/site-packages/py4j/java_gateway.py\", line 929, in _get_connection\n",
      "    connection = self.deque.pop()\n",
      "IndexError: pop from an empty deque\n",
      "\n",
      "During handling of the above exception, another exception occurred:\n",
      "\n",
      "Traceback (most recent call last):\n",
      "  File \"/home/hadoopuser/anaconda3/lib/python3.6/site-packages/py4j/java_gateway.py\", line 1067, in start\n",
      "    self.socket.connect((self.address, self.port))\n",
      "ConnectionRefusedError: [Errno 111] Connection refused\n",
      "ERROR:py4j.java_gateway:An error occurred while trying to connect to the Java server (127.0.0.1:42185)\n",
      "Traceback (most recent call last):\n",
      "  File \"/home/hadoopuser/anaconda3/lib/python3.6/site-packages/py4j/java_gateway.py\", line 929, in _get_connection\n",
      "    connection = self.deque.pop()\n",
      "IndexError: pop from an empty deque\n",
      "\n",
      "During handling of the above exception, another exception occurred:\n",
      "\n",
      "Traceback (most recent call last):\n",
      "  File \"/home/hadoopuser/anaconda3/lib/python3.6/site-packages/py4j/java_gateway.py\", line 1067, in start\n",
      "    self.socket.connect((self.address, self.port))\n",
      "ConnectionRefusedError: [Errno 111] Connection refused\n",
      "ERROR:py4j.java_gateway:An error occurred while trying to connect to the Java server (127.0.0.1:42185)\n",
      "Traceback (most recent call last):\n",
      "  File \"/home/hadoopuser/anaconda3/lib/python3.6/site-packages/py4j/java_gateway.py\", line 929, in _get_connection\n",
      "    connection = self.deque.pop()\n",
      "IndexError: pop from an empty deque\n",
      "\n",
      "During handling of the above exception, another exception occurred:\n",
      "\n",
      "Traceback (most recent call last):\n",
      "  File \"/home/hadoopuser/anaconda3/lib/python3.6/site-packages/py4j/java_gateway.py\", line 1067, in start\n",
      "    self.socket.connect((self.address, self.port))\n",
      "ConnectionRefusedError: [Errno 111] Connection refused\n",
      "ERROR:py4j.java_gateway:An error occurred while trying to connect to the Java server (127.0.0.1:42185)\n",
      "Traceback (most recent call last):\n",
      "  File \"/home/hadoopuser/anaconda3/lib/python3.6/site-packages/py4j/java_gateway.py\", line 929, in _get_connection\n",
      "    connection = self.deque.pop()\n",
      "IndexError: pop from an empty deque\n",
      "\n",
      "During handling of the above exception, another exception occurred:\n",
      "\n",
      "Traceback (most recent call last):\n",
      "  File \"/home/hadoopuser/anaconda3/lib/python3.6/site-packages/py4j/java_gateway.py\", line 1067, in start\n",
      "    self.socket.connect((self.address, self.port))\n",
      "ConnectionRefusedError: [Errno 111] Connection refused\n",
      "ERROR:py4j.java_gateway:An error occurred while trying to connect to the Java server (127.0.0.1:42185)\n",
      "Traceback (most recent call last):\n",
      "  File \"/home/hadoopuser/anaconda3/lib/python3.6/site-packages/py4j/java_gateway.py\", line 929, in _get_connection\n",
      "    connection = self.deque.pop()\n",
      "IndexError: pop from an empty deque\n",
      "\n",
      "During handling of the above exception, another exception occurred:\n",
      "\n",
      "Traceback (most recent call last):\n",
      "  File \"/home/hadoopuser/anaconda3/lib/python3.6/site-packages/py4j/java_gateway.py\", line 1067, in start\n",
      "    self.socket.connect((self.address, self.port))\n",
      "ConnectionRefusedError: [Errno 111] Connection refused\n",
      "ERROR:py4j.java_gateway:An error occurred while trying to connect to the Java server (127.0.0.1:42185)\n",
      "Traceback (most recent call last):\n",
      "  File \"/home/hadoopuser/anaconda3/lib/python3.6/site-packages/py4j/java_gateway.py\", line 929, in _get_connection\n",
      "    connection = self.deque.pop()\n",
      "IndexError: pop from an empty deque\n",
      "\n",
      "During handling of the above exception, another exception occurred:\n",
      "\n",
      "Traceback (most recent call last):\n",
      "  File \"/home/hadoopuser/anaconda3/lib/python3.6/site-packages/py4j/java_gateway.py\", line 1067, in start\n",
      "    self.socket.connect((self.address, self.port))\n",
      "ConnectionRefusedError: [Errno 111] Connection refused\n"
     ]
    },
    {
     "name": "stderr",
     "output_type": "stream",
     "text": [
      "ERROR:py4j.java_gateway:An error occurred while trying to connect to the Java server (127.0.0.1:42185)\n",
      "Traceback (most recent call last):\n",
      "  File \"/home/hadoopuser/anaconda3/lib/python3.6/site-packages/py4j/java_gateway.py\", line 929, in _get_connection\n",
      "    connection = self.deque.pop()\n",
      "IndexError: pop from an empty deque\n",
      "\n",
      "During handling of the above exception, another exception occurred:\n",
      "\n",
      "Traceback (most recent call last):\n",
      "  File \"/home/hadoopuser/anaconda3/lib/python3.6/site-packages/py4j/java_gateway.py\", line 1067, in start\n",
      "    self.socket.connect((self.address, self.port))\n",
      "ConnectionRefusedError: [Errno 111] Connection refused\n",
      "ERROR:py4j.java_gateway:An error occurred while trying to connect to the Java server (127.0.0.1:42185)\n",
      "Traceback (most recent call last):\n",
      "  File \"/home/hadoopuser/anaconda3/lib/python3.6/site-packages/py4j/java_gateway.py\", line 929, in _get_connection\n",
      "    connection = self.deque.pop()\n",
      "IndexError: pop from an empty deque\n",
      "\n",
      "During handling of the above exception, another exception occurred:\n",
      "\n",
      "Traceback (most recent call last):\n",
      "  File \"/home/hadoopuser/anaconda3/lib/python3.6/site-packages/py4j/java_gateway.py\", line 1067, in start\n",
      "    self.socket.connect((self.address, self.port))\n",
      "ConnectionRefusedError: [Errno 111] Connection refused\n",
      "ERROR:py4j.java_gateway:An error occurred while trying to connect to the Java server (127.0.0.1:42185)\n",
      "Traceback (most recent call last):\n",
      "  File \"/home/hadoopuser/anaconda3/lib/python3.6/site-packages/py4j/java_gateway.py\", line 929, in _get_connection\n",
      "    connection = self.deque.pop()\n",
      "IndexError: pop from an empty deque\n",
      "\n",
      "During handling of the above exception, another exception occurred:\n",
      "\n",
      "Traceback (most recent call last):\n",
      "  File \"/home/hadoopuser/anaconda3/lib/python3.6/site-packages/py4j/java_gateway.py\", line 1067, in start\n",
      "    self.socket.connect((self.address, self.port))\n",
      "ConnectionRefusedError: [Errno 111] Connection refused\n",
      "ERROR:py4j.java_gateway:An error occurred while trying to connect to the Java server (127.0.0.1:42185)\n",
      "Traceback (most recent call last):\n",
      "  File \"/home/hadoopuser/anaconda3/lib/python3.6/site-packages/py4j/java_gateway.py\", line 929, in _get_connection\n",
      "    connection = self.deque.pop()\n",
      "IndexError: pop from an empty deque\n",
      "\n",
      "During handling of the above exception, another exception occurred:\n",
      "\n",
      "Traceback (most recent call last):\n",
      "  File \"/home/hadoopuser/anaconda3/lib/python3.6/site-packages/py4j/java_gateway.py\", line 1067, in start\n",
      "    self.socket.connect((self.address, self.port))\n",
      "ConnectionRefusedError: [Errno 111] Connection refused\n",
      "ERROR:py4j.java_gateway:An error occurred while trying to connect to the Java server (127.0.0.1:42185)\n",
      "Traceback (most recent call last):\n",
      "  File \"/home/hadoopuser/anaconda3/lib/python3.6/site-packages/py4j/java_gateway.py\", line 929, in _get_connection\n",
      "    connection = self.deque.pop()\n",
      "IndexError: pop from an empty deque\n",
      "\n",
      "During handling of the above exception, another exception occurred:\n",
      "\n",
      "Traceback (most recent call last):\n",
      "  File \"/home/hadoopuser/anaconda3/lib/python3.6/site-packages/py4j/java_gateway.py\", line 1067, in start\n",
      "    self.socket.connect((self.address, self.port))\n",
      "ConnectionRefusedError: [Errno 111] Connection refused\n",
      "ERROR:py4j.java_gateway:An error occurred while trying to connect to the Java server (127.0.0.1:42185)\n",
      "Traceback (most recent call last):\n",
      "  File \"/home/hadoopuser/anaconda3/lib/python3.6/site-packages/py4j/java_gateway.py\", line 929, in _get_connection\n",
      "    connection = self.deque.pop()\n",
      "IndexError: pop from an empty deque\n",
      "\n",
      "During handling of the above exception, another exception occurred:\n",
      "\n",
      "Traceback (most recent call last):\n",
      "  File \"/home/hadoopuser/anaconda3/lib/python3.6/site-packages/py4j/java_gateway.py\", line 1067, in start\n",
      "    self.socket.connect((self.address, self.port))\n",
      "ConnectionRefusedError: [Errno 111] Connection refused\n",
      "ERROR:py4j.java_gateway:An error occurred while trying to connect to the Java server (127.0.0.1:42185)\n",
      "Traceback (most recent call last):\n",
      "  File \"/home/hadoopuser/anaconda3/lib/python3.6/site-packages/py4j/java_gateway.py\", line 929, in _get_connection\n",
      "    connection = self.deque.pop()\n",
      "IndexError: pop from an empty deque\n",
      "\n",
      "During handling of the above exception, another exception occurred:\n",
      "\n",
      "Traceback (most recent call last):\n",
      "  File \"/home/hadoopuser/anaconda3/lib/python3.6/site-packages/py4j/java_gateway.py\", line 1067, in start\n",
      "    self.socket.connect((self.address, self.port))\n",
      "ConnectionRefusedError: [Errno 111] Connection refused\n",
      "ERROR:py4j.java_gateway:An error occurred while trying to connect to the Java server (127.0.0.1:42185)\n",
      "Traceback (most recent call last):\n",
      "  File \"/home/hadoopuser/anaconda3/lib/python3.6/site-packages/py4j/java_gateway.py\", line 929, in _get_connection\n",
      "    connection = self.deque.pop()\n",
      "IndexError: pop from an empty deque\n",
      "\n",
      "During handling of the above exception, another exception occurred:\n",
      "\n",
      "Traceback (most recent call last):\n",
      "  File \"/home/hadoopuser/anaconda3/lib/python3.6/site-packages/py4j/java_gateway.py\", line 1067, in start\n",
      "    self.socket.connect((self.address, self.port))\n",
      "ConnectionRefusedError: [Errno 111] Connection refused\n",
      "ERROR:py4j.java_gateway:An error occurred while trying to connect to the Java server (127.0.0.1:42185)\n",
      "Traceback (most recent call last):\n",
      "  File \"/home/hadoopuser/anaconda3/lib/python3.6/site-packages/py4j/java_gateway.py\", line 929, in _get_connection\n",
      "    connection = self.deque.pop()\n",
      "IndexError: pop from an empty deque\n",
      "\n",
      "During handling of the above exception, another exception occurred:\n",
      "\n",
      "Traceback (most recent call last):\n",
      "  File \"/home/hadoopuser/anaconda3/lib/python3.6/site-packages/py4j/java_gateway.py\", line 1067, in start\n",
      "    self.socket.connect((self.address, self.port))\n",
      "ConnectionRefusedError: [Errno 111] Connection refused\n",
      "ERROR:py4j.java_gateway:An error occurred while trying to connect to the Java server (127.0.0.1:42185)\n",
      "Traceback (most recent call last):\n",
      "  File \"/home/hadoopuser/anaconda3/lib/python3.6/site-packages/py4j/java_gateway.py\", line 929, in _get_connection\n",
      "    connection = self.deque.pop()\n",
      "IndexError: pop from an empty deque\n",
      "\n",
      "During handling of the above exception, another exception occurred:\n",
      "\n",
      "Traceback (most recent call last):\n",
      "  File \"/home/hadoopuser/anaconda3/lib/python3.6/site-packages/py4j/java_gateway.py\", line 1067, in start\n",
      "    self.socket.connect((self.address, self.port))\n",
      "ConnectionRefusedError: [Errno 111] Connection refused\n",
      "ERROR:py4j.java_gateway:An error occurred while trying to connect to the Java server (127.0.0.1:42185)\n",
      "Traceback (most recent call last):\n",
      "  File \"/home/hadoopuser/anaconda3/lib/python3.6/site-packages/py4j/java_gateway.py\", line 929, in _get_connection\n",
      "    connection = self.deque.pop()\n",
      "IndexError: pop from an empty deque\n",
      "\n",
      "During handling of the above exception, another exception occurred:\n",
      "\n",
      "Traceback (most recent call last):\n",
      "  File \"/home/hadoopuser/anaconda3/lib/python3.6/site-packages/py4j/java_gateway.py\", line 1067, in start\n",
      "    self.socket.connect((self.address, self.port))\n",
      "ConnectionRefusedError: [Errno 111] Connection refused\n",
      "ERROR:py4j.java_gateway:An error occurred while trying to connect to the Java server (127.0.0.1:42185)\n",
      "Traceback (most recent call last):\n",
      "  File \"/home/hadoopuser/anaconda3/lib/python3.6/site-packages/py4j/java_gateway.py\", line 929, in _get_connection\n",
      "    connection = self.deque.pop()\n",
      "IndexError: pop from an empty deque\n",
      "\n",
      "During handling of the above exception, another exception occurred:\n",
      "\n",
      "Traceback (most recent call last):\n",
      "  File \"/home/hadoopuser/anaconda3/lib/python3.6/site-packages/py4j/java_gateway.py\", line 1067, in start\n",
      "    self.socket.connect((self.address, self.port))\n",
      "ConnectionRefusedError: [Errno 111] Connection refused\n",
      "ERROR:py4j.java_gateway:An error occurred while trying to connect to the Java server (127.0.0.1:42185)\n",
      "Traceback (most recent call last):\n",
      "  File \"/home/hadoopuser/anaconda3/lib/python3.6/site-packages/py4j/java_gateway.py\", line 929, in _get_connection\n",
      "    connection = self.deque.pop()\n",
      "IndexError: pop from an empty deque\n",
      "\n",
      "During handling of the above exception, another exception occurred:\n",
      "\n",
      "Traceback (most recent call last):\n",
      "  File \"/home/hadoopuser/anaconda3/lib/python3.6/site-packages/py4j/java_gateway.py\", line 1067, in start\n",
      "    self.socket.connect((self.address, self.port))\n",
      "ConnectionRefusedError: [Errno 111] Connection refused\n"
     ]
    },
    {
     "name": "stderr",
     "output_type": "stream",
     "text": [
      "ERROR:py4j.java_gateway:An error occurred while trying to connect to the Java server (127.0.0.1:42185)\n",
      "Traceback (most recent call last):\n",
      "  File \"/home/hadoopuser/anaconda3/lib/python3.6/site-packages/py4j/java_gateway.py\", line 929, in _get_connection\n",
      "    connection = self.deque.pop()\n",
      "IndexError: pop from an empty deque\n",
      "\n",
      "During handling of the above exception, another exception occurred:\n",
      "\n",
      "Traceback (most recent call last):\n",
      "  File \"/home/hadoopuser/anaconda3/lib/python3.6/site-packages/py4j/java_gateway.py\", line 1067, in start\n",
      "    self.socket.connect((self.address, self.port))\n",
      "ConnectionRefusedError: [Errno 111] Connection refused\n",
      "ERROR:py4j.java_gateway:An error occurred while trying to connect to the Java server (127.0.0.1:42185)\n",
      "Traceback (most recent call last):\n",
      "  File \"/home/hadoopuser/anaconda3/lib/python3.6/site-packages/py4j/java_gateway.py\", line 929, in _get_connection\n",
      "    connection = self.deque.pop()\n",
      "IndexError: pop from an empty deque\n",
      "\n",
      "During handling of the above exception, another exception occurred:\n",
      "\n",
      "Traceback (most recent call last):\n",
      "  File \"/home/hadoopuser/anaconda3/lib/python3.6/site-packages/py4j/java_gateway.py\", line 1067, in start\n",
      "    self.socket.connect((self.address, self.port))\n",
      "ConnectionRefusedError: [Errno 111] Connection refused\n",
      "ERROR:py4j.java_gateway:An error occurred while trying to connect to the Java server (127.0.0.1:42185)\n",
      "Traceback (most recent call last):\n",
      "  File \"/home/hadoopuser/anaconda3/lib/python3.6/site-packages/py4j/java_gateway.py\", line 929, in _get_connection\n",
      "    connection = self.deque.pop()\n",
      "IndexError: pop from an empty deque\n",
      "\n",
      "During handling of the above exception, another exception occurred:\n",
      "\n",
      "Traceback (most recent call last):\n",
      "  File \"/home/hadoopuser/anaconda3/lib/python3.6/site-packages/py4j/java_gateway.py\", line 1067, in start\n",
      "    self.socket.connect((self.address, self.port))\n",
      "ConnectionRefusedError: [Errno 111] Connection refused\n",
      "ERROR:py4j.java_gateway:An error occurred while trying to connect to the Java server (127.0.0.1:42185)\n",
      "Traceback (most recent call last):\n",
      "  File \"/home/hadoopuser/anaconda3/lib/python3.6/site-packages/py4j/java_gateway.py\", line 929, in _get_connection\n",
      "    connection = self.deque.pop()\n",
      "IndexError: pop from an empty deque\n",
      "\n",
      "During handling of the above exception, another exception occurred:\n",
      "\n",
      "Traceback (most recent call last):\n",
      "  File \"/home/hadoopuser/anaconda3/lib/python3.6/site-packages/py4j/java_gateway.py\", line 1067, in start\n",
      "    self.socket.connect((self.address, self.port))\n",
      "ConnectionRefusedError: [Errno 111] Connection refused\n",
      "ERROR:py4j.java_gateway:An error occurred while trying to connect to the Java server (127.0.0.1:42185)\n",
      "Traceback (most recent call last):\n",
      "  File \"/home/hadoopuser/anaconda3/lib/python3.6/site-packages/py4j/java_gateway.py\", line 929, in _get_connection\n",
      "    connection = self.deque.pop()\n",
      "IndexError: pop from an empty deque\n",
      "\n",
      "During handling of the above exception, another exception occurred:\n",
      "\n",
      "Traceback (most recent call last):\n",
      "  File \"/home/hadoopuser/anaconda3/lib/python3.6/site-packages/py4j/java_gateway.py\", line 1067, in start\n",
      "    self.socket.connect((self.address, self.port))\n",
      "ConnectionRefusedError: [Errno 111] Connection refused\n",
      "ERROR:py4j.java_gateway:An error occurred while trying to connect to the Java server (127.0.0.1:42185)\n",
      "Traceback (most recent call last):\n",
      "  File \"/home/hadoopuser/anaconda3/lib/python3.6/site-packages/py4j/java_gateway.py\", line 929, in _get_connection\n",
      "    connection = self.deque.pop()\n",
      "IndexError: pop from an empty deque\n",
      "\n",
      "During handling of the above exception, another exception occurred:\n",
      "\n",
      "Traceback (most recent call last):\n",
      "  File \"/home/hadoopuser/anaconda3/lib/python3.6/site-packages/py4j/java_gateway.py\", line 1067, in start\n",
      "    self.socket.connect((self.address, self.port))\n",
      "ConnectionRefusedError: [Errno 111] Connection refused\n",
      "ERROR:py4j.java_gateway:An error occurred while trying to connect to the Java server (127.0.0.1:42185)\n",
      "Traceback (most recent call last):\n",
      "  File \"/home/hadoopuser/anaconda3/lib/python3.6/site-packages/py4j/java_gateway.py\", line 929, in _get_connection\n",
      "    connection = self.deque.pop()\n",
      "IndexError: pop from an empty deque\n",
      "\n",
      "During handling of the above exception, another exception occurred:\n",
      "\n",
      "Traceback (most recent call last):\n",
      "  File \"/home/hadoopuser/anaconda3/lib/python3.6/site-packages/py4j/java_gateway.py\", line 1067, in start\n",
      "    self.socket.connect((self.address, self.port))\n",
      "ConnectionRefusedError: [Errno 111] Connection refused\n",
      "ERROR:py4j.java_gateway:An error occurred while trying to connect to the Java server (127.0.0.1:42185)\n",
      "Traceback (most recent call last):\n",
      "  File \"/home/hadoopuser/anaconda3/lib/python3.6/site-packages/py4j/java_gateway.py\", line 929, in _get_connection\n",
      "    connection = self.deque.pop()\n",
      "IndexError: pop from an empty deque\n",
      "\n",
      "During handling of the above exception, another exception occurred:\n",
      "\n",
      "Traceback (most recent call last):\n",
      "  File \"/home/hadoopuser/anaconda3/lib/python3.6/site-packages/py4j/java_gateway.py\", line 1067, in start\n",
      "    self.socket.connect((self.address, self.port))\n",
      "ConnectionRefusedError: [Errno 111] Connection refused\n",
      "ERROR:py4j.java_gateway:An error occurred while trying to connect to the Java server (127.0.0.1:42185)\n",
      "Traceback (most recent call last):\n",
      "  File \"/home/hadoopuser/anaconda3/lib/python3.6/site-packages/py4j/java_gateway.py\", line 929, in _get_connection\n",
      "    connection = self.deque.pop()\n",
      "IndexError: pop from an empty deque\n",
      "\n",
      "During handling of the above exception, another exception occurred:\n",
      "\n",
      "Traceback (most recent call last):\n",
      "  File \"/home/hadoopuser/anaconda3/lib/python3.6/site-packages/py4j/java_gateway.py\", line 1067, in start\n",
      "    self.socket.connect((self.address, self.port))\n",
      "ConnectionRefusedError: [Errno 111] Connection refused\n",
      "ERROR:py4j.java_gateway:An error occurred while trying to connect to the Java server (127.0.0.1:42185)\n",
      "Traceback (most recent call last):\n",
      "  File \"/home/hadoopuser/anaconda3/lib/python3.6/site-packages/py4j/java_gateway.py\", line 929, in _get_connection\n",
      "    connection = self.deque.pop()\n",
      "IndexError: pop from an empty deque\n",
      "\n",
      "During handling of the above exception, another exception occurred:\n",
      "\n",
      "Traceback (most recent call last):\n",
      "  File \"/home/hadoopuser/anaconda3/lib/python3.6/site-packages/py4j/java_gateway.py\", line 1067, in start\n",
      "    self.socket.connect((self.address, self.port))\n",
      "ConnectionRefusedError: [Errno 111] Connection refused\n",
      "ERROR:py4j.java_gateway:An error occurred while trying to connect to the Java server (127.0.0.1:42185)\n",
      "Traceback (most recent call last):\n",
      "  File \"/home/hadoopuser/anaconda3/lib/python3.6/site-packages/py4j/java_gateway.py\", line 929, in _get_connection\n",
      "    connection = self.deque.pop()\n",
      "IndexError: pop from an empty deque\n",
      "\n",
      "During handling of the above exception, another exception occurred:\n",
      "\n",
      "Traceback (most recent call last):\n",
      "  File \"/home/hadoopuser/anaconda3/lib/python3.6/site-packages/py4j/java_gateway.py\", line 1067, in start\n",
      "    self.socket.connect((self.address, self.port))\n",
      "ConnectionRefusedError: [Errno 111] Connection refused\n",
      "ERROR:py4j.java_gateway:An error occurred while trying to connect to the Java server (127.0.0.1:42185)\n",
      "Traceback (most recent call last):\n",
      "  File \"/home/hadoopuser/anaconda3/lib/python3.6/site-packages/py4j/java_gateway.py\", line 929, in _get_connection\n",
      "    connection = self.deque.pop()\n",
      "IndexError: pop from an empty deque\n",
      "\n",
      "During handling of the above exception, another exception occurred:\n",
      "\n",
      "Traceback (most recent call last):\n",
      "  File \"/home/hadoopuser/anaconda3/lib/python3.6/site-packages/py4j/java_gateway.py\", line 1067, in start\n",
      "    self.socket.connect((self.address, self.port))\n",
      "ConnectionRefusedError: [Errno 111] Connection refused\n",
      "ERROR:py4j.java_gateway:An error occurred while trying to connect to the Java server (127.0.0.1:42185)\n",
      "Traceback (most recent call last):\n",
      "  File \"/home/hadoopuser/anaconda3/lib/python3.6/site-packages/py4j/java_gateway.py\", line 929, in _get_connection\n",
      "    connection = self.deque.pop()\n",
      "IndexError: pop from an empty deque\n",
      "\n",
      "During handling of the above exception, another exception occurred:\n",
      "\n",
      "Traceback (most recent call last):\n",
      "  File \"/home/hadoopuser/anaconda3/lib/python3.6/site-packages/py4j/java_gateway.py\", line 1067, in start\n",
      "    self.socket.connect((self.address, self.port))\n",
      "ConnectionRefusedError: [Errno 111] Connection refused\n"
     ]
    },
    {
     "name": "stderr",
     "output_type": "stream",
     "text": [
      "ERROR:py4j.java_gateway:An error occurred while trying to connect to the Java server (127.0.0.1:42185)\n",
      "Traceback (most recent call last):\n",
      "  File \"/home/hadoopuser/anaconda3/lib/python3.6/site-packages/py4j/java_gateway.py\", line 929, in _get_connection\n",
      "    connection = self.deque.pop()\n",
      "IndexError: pop from an empty deque\n",
      "\n",
      "During handling of the above exception, another exception occurred:\n",
      "\n",
      "Traceback (most recent call last):\n",
      "  File \"/home/hadoopuser/anaconda3/lib/python3.6/site-packages/py4j/java_gateway.py\", line 1067, in start\n",
      "    self.socket.connect((self.address, self.port))\n",
      "ConnectionRefusedError: [Errno 111] Connection refused\n",
      "ERROR:py4j.java_gateway:An error occurred while trying to connect to the Java server (127.0.0.1:42185)\n",
      "Traceback (most recent call last):\n",
      "  File \"/home/hadoopuser/anaconda3/lib/python3.6/site-packages/py4j/java_gateway.py\", line 929, in _get_connection\n",
      "    connection = self.deque.pop()\n",
      "IndexError: pop from an empty deque\n",
      "\n",
      "During handling of the above exception, another exception occurred:\n",
      "\n",
      "Traceback (most recent call last):\n",
      "  File \"/home/hadoopuser/anaconda3/lib/python3.6/site-packages/py4j/java_gateway.py\", line 1067, in start\n",
      "    self.socket.connect((self.address, self.port))\n",
      "ConnectionRefusedError: [Errno 111] Connection refused\n",
      "ERROR:py4j.java_gateway:An error occurred while trying to connect to the Java server (127.0.0.1:42185)\n",
      "Traceback (most recent call last):\n",
      "  File \"/home/hadoopuser/anaconda3/lib/python3.6/site-packages/py4j/java_gateway.py\", line 929, in _get_connection\n",
      "    connection = self.deque.pop()\n",
      "IndexError: pop from an empty deque\n",
      "\n",
      "During handling of the above exception, another exception occurred:\n",
      "\n",
      "Traceback (most recent call last):\n",
      "  File \"/home/hadoopuser/anaconda3/lib/python3.6/site-packages/py4j/java_gateway.py\", line 1067, in start\n",
      "    self.socket.connect((self.address, self.port))\n",
      "ConnectionRefusedError: [Errno 111] Connection refused\n",
      "ERROR:py4j.java_gateway:An error occurred while trying to connect to the Java server (127.0.0.1:42185)\n",
      "Traceback (most recent call last):\n",
      "  File \"/home/hadoopuser/anaconda3/lib/python3.6/site-packages/py4j/java_gateway.py\", line 929, in _get_connection\n",
      "    connection = self.deque.pop()\n",
      "IndexError: pop from an empty deque\n",
      "\n",
      "During handling of the above exception, another exception occurred:\n",
      "\n",
      "Traceback (most recent call last):\n",
      "  File \"/home/hadoopuser/anaconda3/lib/python3.6/site-packages/py4j/java_gateway.py\", line 1067, in start\n",
      "    self.socket.connect((self.address, self.port))\n",
      "ConnectionRefusedError: [Errno 111] Connection refused\n",
      "ERROR:py4j.java_gateway:An error occurred while trying to connect to the Java server (127.0.0.1:42185)\n",
      "Traceback (most recent call last):\n",
      "  File \"/home/hadoopuser/anaconda3/lib/python3.6/site-packages/py4j/java_gateway.py\", line 929, in _get_connection\n",
      "    connection = self.deque.pop()\n",
      "IndexError: pop from an empty deque\n",
      "\n",
      "During handling of the above exception, another exception occurred:\n",
      "\n",
      "Traceback (most recent call last):\n",
      "  File \"/home/hadoopuser/anaconda3/lib/python3.6/site-packages/py4j/java_gateway.py\", line 1067, in start\n",
      "    self.socket.connect((self.address, self.port))\n",
      "ConnectionRefusedError: [Errno 111] Connection refused\n",
      "ERROR:py4j.java_gateway:An error occurred while trying to connect to the Java server (127.0.0.1:42185)\n",
      "Traceback (most recent call last):\n",
      "  File \"/home/hadoopuser/anaconda3/lib/python3.6/site-packages/py4j/java_gateway.py\", line 929, in _get_connection\n",
      "    connection = self.deque.pop()\n",
      "IndexError: pop from an empty deque\n",
      "\n",
      "During handling of the above exception, another exception occurred:\n",
      "\n",
      "Traceback (most recent call last):\n",
      "  File \"/home/hadoopuser/anaconda3/lib/python3.6/site-packages/py4j/java_gateway.py\", line 1067, in start\n",
      "    self.socket.connect((self.address, self.port))\n",
      "ConnectionRefusedError: [Errno 111] Connection refused\n",
      "ERROR:py4j.java_gateway:An error occurred while trying to connect to the Java server (127.0.0.1:42185)\n",
      "Traceback (most recent call last):\n",
      "  File \"/home/hadoopuser/anaconda3/lib/python3.6/site-packages/py4j/java_gateway.py\", line 929, in _get_connection\n",
      "    connection = self.deque.pop()\n",
      "IndexError: pop from an empty deque\n",
      "\n",
      "During handling of the above exception, another exception occurred:\n",
      "\n",
      "Traceback (most recent call last):\n",
      "  File \"/home/hadoopuser/anaconda3/lib/python3.6/site-packages/py4j/java_gateway.py\", line 1067, in start\n",
      "    self.socket.connect((self.address, self.port))\n",
      "ConnectionRefusedError: [Errno 111] Connection refused\n",
      "ERROR:py4j.java_gateway:An error occurred while trying to connect to the Java server (127.0.0.1:42185)\n",
      "Traceback (most recent call last):\n",
      "  File \"/home/hadoopuser/anaconda3/lib/python3.6/site-packages/py4j/java_gateway.py\", line 929, in _get_connection\n",
      "    connection = self.deque.pop()\n",
      "IndexError: pop from an empty deque\n",
      "\n",
      "During handling of the above exception, another exception occurred:\n",
      "\n",
      "Traceback (most recent call last):\n",
      "  File \"/home/hadoopuser/anaconda3/lib/python3.6/site-packages/py4j/java_gateway.py\", line 1067, in start\n",
      "    self.socket.connect((self.address, self.port))\n",
      "ConnectionRefusedError: [Errno 111] Connection refused\n",
      "ERROR:py4j.java_gateway:An error occurred while trying to connect to the Java server (127.0.0.1:42185)\n",
      "Traceback (most recent call last):\n",
      "  File \"/home/hadoopuser/anaconda3/lib/python3.6/site-packages/py4j/java_gateway.py\", line 929, in _get_connection\n",
      "    connection = self.deque.pop()\n",
      "IndexError: pop from an empty deque\n",
      "\n",
      "During handling of the above exception, another exception occurred:\n",
      "\n",
      "Traceback (most recent call last):\n",
      "  File \"/home/hadoopuser/anaconda3/lib/python3.6/site-packages/py4j/java_gateway.py\", line 1067, in start\n",
      "    self.socket.connect((self.address, self.port))\n",
      "ConnectionRefusedError: [Errno 111] Connection refused\n",
      "ERROR:py4j.java_gateway:An error occurred while trying to connect to the Java server (127.0.0.1:42185)\n",
      "Traceback (most recent call last):\n",
      "  File \"/home/hadoopuser/anaconda3/lib/python3.6/site-packages/py4j/java_gateway.py\", line 929, in _get_connection\n",
      "    connection = self.deque.pop()\n",
      "IndexError: pop from an empty deque\n",
      "\n",
      "During handling of the above exception, another exception occurred:\n",
      "\n",
      "Traceback (most recent call last):\n",
      "  File \"/home/hadoopuser/anaconda3/lib/python3.6/site-packages/py4j/java_gateway.py\", line 1067, in start\n",
      "    self.socket.connect((self.address, self.port))\n",
      "ConnectionRefusedError: [Errno 111] Connection refused\n",
      "ERROR:py4j.java_gateway:An error occurred while trying to connect to the Java server (127.0.0.1:42185)\n",
      "Traceback (most recent call last):\n",
      "  File \"/home/hadoopuser/anaconda3/lib/python3.6/site-packages/py4j/java_gateway.py\", line 929, in _get_connection\n",
      "    connection = self.deque.pop()\n",
      "IndexError: pop from an empty deque\n",
      "\n",
      "During handling of the above exception, another exception occurred:\n",
      "\n",
      "Traceback (most recent call last):\n",
      "  File \"/home/hadoopuser/anaconda3/lib/python3.6/site-packages/py4j/java_gateway.py\", line 1067, in start\n",
      "    self.socket.connect((self.address, self.port))\n",
      "ConnectionRefusedError: [Errno 111] Connection refused\n",
      "ERROR:py4j.java_gateway:An error occurred while trying to connect to the Java server (127.0.0.1:42185)\n",
      "Traceback (most recent call last):\n",
      "  File \"/home/hadoopuser/anaconda3/lib/python3.6/site-packages/py4j/java_gateway.py\", line 929, in _get_connection\n",
      "    connection = self.deque.pop()\n",
      "IndexError: pop from an empty deque\n",
      "\n",
      "During handling of the above exception, another exception occurred:\n",
      "\n",
      "Traceback (most recent call last):\n",
      "  File \"/home/hadoopuser/anaconda3/lib/python3.6/site-packages/py4j/java_gateway.py\", line 1067, in start\n",
      "    self.socket.connect((self.address, self.port))\n",
      "ConnectionRefusedError: [Errno 111] Connection refused\n",
      "ERROR:py4j.java_gateway:An error occurred while trying to connect to the Java server (127.0.0.1:42185)\n",
      "Traceback (most recent call last):\n",
      "  File \"/home/hadoopuser/anaconda3/lib/python3.6/site-packages/py4j/java_gateway.py\", line 929, in _get_connection\n",
      "    connection = self.deque.pop()\n",
      "IndexError: pop from an empty deque\n",
      "\n",
      "During handling of the above exception, another exception occurred:\n",
      "\n",
      "Traceback (most recent call last):\n",
      "  File \"/home/hadoopuser/anaconda3/lib/python3.6/site-packages/py4j/java_gateway.py\", line 1067, in start\n",
      "    self.socket.connect((self.address, self.port))\n",
      "ConnectionRefusedError: [Errno 111] Connection refused\n"
     ]
    },
    {
     "name": "stderr",
     "output_type": "stream",
     "text": [
      "ERROR:py4j.java_gateway:An error occurred while trying to connect to the Java server (127.0.0.1:42185)\n",
      "Traceback (most recent call last):\n",
      "  File \"/home/hadoopuser/anaconda3/lib/python3.6/site-packages/py4j/java_gateway.py\", line 929, in _get_connection\n",
      "    connection = self.deque.pop()\n",
      "IndexError: pop from an empty deque\n",
      "\n",
      "During handling of the above exception, another exception occurred:\n",
      "\n",
      "Traceback (most recent call last):\n",
      "  File \"/home/hadoopuser/anaconda3/lib/python3.6/site-packages/py4j/java_gateway.py\", line 1067, in start\n",
      "    self.socket.connect((self.address, self.port))\n",
      "ConnectionRefusedError: [Errno 111] Connection refused\n",
      "ERROR:py4j.java_gateway:An error occurred while trying to connect to the Java server (127.0.0.1:42185)\n",
      "Traceback (most recent call last):\n",
      "  File \"/home/hadoopuser/anaconda3/lib/python3.6/site-packages/py4j/java_gateway.py\", line 929, in _get_connection\n",
      "    connection = self.deque.pop()\n",
      "IndexError: pop from an empty deque\n",
      "\n",
      "During handling of the above exception, another exception occurred:\n",
      "\n",
      "Traceback (most recent call last):\n",
      "  File \"/home/hadoopuser/anaconda3/lib/python3.6/site-packages/py4j/java_gateway.py\", line 1067, in start\n",
      "    self.socket.connect((self.address, self.port))\n",
      "ConnectionRefusedError: [Errno 111] Connection refused\n",
      "ERROR:py4j.java_gateway:An error occurred while trying to connect to the Java server (127.0.0.1:42185)\n",
      "Traceback (most recent call last):\n",
      "  File \"/home/hadoopuser/anaconda3/lib/python3.6/site-packages/py4j/java_gateway.py\", line 929, in _get_connection\n",
      "    connection = self.deque.pop()\n",
      "IndexError: pop from an empty deque\n",
      "\n",
      "During handling of the above exception, another exception occurred:\n",
      "\n",
      "Traceback (most recent call last):\n",
      "  File \"/home/hadoopuser/anaconda3/lib/python3.6/site-packages/py4j/java_gateway.py\", line 1067, in start\n",
      "    self.socket.connect((self.address, self.port))\n",
      "ConnectionRefusedError: [Errno 111] Connection refused\n",
      "ERROR:py4j.java_gateway:An error occurred while trying to connect to the Java server (127.0.0.1:42185)\n",
      "Traceback (most recent call last):\n",
      "  File \"/home/hadoopuser/anaconda3/lib/python3.6/site-packages/py4j/java_gateway.py\", line 929, in _get_connection\n",
      "    connection = self.deque.pop()\n",
      "IndexError: pop from an empty deque\n",
      "\n",
      "During handling of the above exception, another exception occurred:\n",
      "\n",
      "Traceback (most recent call last):\n",
      "  File \"/home/hadoopuser/anaconda3/lib/python3.6/site-packages/py4j/java_gateway.py\", line 1067, in start\n",
      "    self.socket.connect((self.address, self.port))\n",
      "ConnectionRefusedError: [Errno 111] Connection refused\n",
      "ERROR:py4j.java_gateway:An error occurred while trying to connect to the Java server (127.0.0.1:42185)\n",
      "Traceback (most recent call last):\n",
      "  File \"/home/hadoopuser/anaconda3/lib/python3.6/site-packages/py4j/java_gateway.py\", line 929, in _get_connection\n",
      "    connection = self.deque.pop()\n",
      "IndexError: pop from an empty deque\n",
      "\n",
      "During handling of the above exception, another exception occurred:\n",
      "\n",
      "Traceback (most recent call last):\n",
      "  File \"/home/hadoopuser/anaconda3/lib/python3.6/site-packages/py4j/java_gateway.py\", line 1067, in start\n",
      "    self.socket.connect((self.address, self.port))\n",
      "ConnectionRefusedError: [Errno 111] Connection refused\n",
      "ERROR:py4j.java_gateway:An error occurred while trying to connect to the Java server (127.0.0.1:42185)\n",
      "Traceback (most recent call last):\n",
      "  File \"/home/hadoopuser/anaconda3/lib/python3.6/site-packages/py4j/java_gateway.py\", line 929, in _get_connection\n",
      "    connection = self.deque.pop()\n",
      "IndexError: pop from an empty deque\n",
      "\n",
      "During handling of the above exception, another exception occurred:\n",
      "\n",
      "Traceback (most recent call last):\n",
      "  File \"/home/hadoopuser/anaconda3/lib/python3.6/site-packages/py4j/java_gateway.py\", line 1067, in start\n",
      "    self.socket.connect((self.address, self.port))\n",
      "ConnectionRefusedError: [Errno 111] Connection refused\n",
      "ERROR:py4j.java_gateway:An error occurred while trying to connect to the Java server (127.0.0.1:42185)\n",
      "Traceback (most recent call last):\n",
      "  File \"/home/hadoopuser/anaconda3/lib/python3.6/site-packages/py4j/java_gateway.py\", line 929, in _get_connection\n",
      "    connection = self.deque.pop()\n",
      "IndexError: pop from an empty deque\n",
      "\n",
      "During handling of the above exception, another exception occurred:\n",
      "\n",
      "Traceback (most recent call last):\n",
      "  File \"/home/hadoopuser/anaconda3/lib/python3.6/site-packages/py4j/java_gateway.py\", line 1067, in start\n",
      "    self.socket.connect((self.address, self.port))\n",
      "ConnectionRefusedError: [Errno 111] Connection refused\n",
      "ERROR:py4j.java_gateway:An error occurred while trying to connect to the Java server (127.0.0.1:42185)\n",
      "Traceback (most recent call last):\n",
      "  File \"/home/hadoopuser/anaconda3/lib/python3.6/site-packages/py4j/java_gateway.py\", line 929, in _get_connection\n",
      "    connection = self.deque.pop()\n",
      "IndexError: pop from an empty deque\n",
      "\n",
      "During handling of the above exception, another exception occurred:\n",
      "\n",
      "Traceback (most recent call last):\n",
      "  File \"/home/hadoopuser/anaconda3/lib/python3.6/site-packages/py4j/java_gateway.py\", line 1067, in start\n",
      "    self.socket.connect((self.address, self.port))\n",
      "ConnectionRefusedError: [Errno 111] Connection refused\n",
      "ERROR:py4j.java_gateway:An error occurred while trying to connect to the Java server (127.0.0.1:42185)\n",
      "Traceback (most recent call last):\n",
      "  File \"/home/hadoopuser/anaconda3/lib/python3.6/site-packages/py4j/java_gateway.py\", line 929, in _get_connection\n",
      "    connection = self.deque.pop()\n",
      "IndexError: pop from an empty deque\n",
      "\n",
      "During handling of the above exception, another exception occurred:\n",
      "\n",
      "Traceback (most recent call last):\n",
      "  File \"/home/hadoopuser/anaconda3/lib/python3.6/site-packages/py4j/java_gateway.py\", line 1067, in start\n",
      "    self.socket.connect((self.address, self.port))\n",
      "ConnectionRefusedError: [Errno 111] Connection refused\n",
      "ERROR:py4j.java_gateway:An error occurred while trying to connect to the Java server (127.0.0.1:42185)\n",
      "Traceback (most recent call last):\n",
      "  File \"/home/hadoopuser/anaconda3/lib/python3.6/site-packages/py4j/java_gateway.py\", line 929, in _get_connection\n",
      "    connection = self.deque.pop()\n",
      "IndexError: pop from an empty deque\n",
      "\n",
      "During handling of the above exception, another exception occurred:\n",
      "\n",
      "Traceback (most recent call last):\n",
      "  File \"/home/hadoopuser/anaconda3/lib/python3.6/site-packages/py4j/java_gateway.py\", line 1067, in start\n",
      "    self.socket.connect((self.address, self.port))\n",
      "ConnectionRefusedError: [Errno 111] Connection refused\n",
      "ERROR:py4j.java_gateway:An error occurred while trying to connect to the Java server (127.0.0.1:42185)\n",
      "Traceback (most recent call last):\n",
      "  File \"/home/hadoopuser/anaconda3/lib/python3.6/site-packages/py4j/java_gateway.py\", line 929, in _get_connection\n",
      "    connection = self.deque.pop()\n",
      "IndexError: pop from an empty deque\n",
      "\n",
      "During handling of the above exception, another exception occurred:\n",
      "\n",
      "Traceback (most recent call last):\n",
      "  File \"/home/hadoopuser/anaconda3/lib/python3.6/site-packages/py4j/java_gateway.py\", line 1067, in start\n",
      "    self.socket.connect((self.address, self.port))\n",
      "ConnectionRefusedError: [Errno 111] Connection refused\n",
      "ERROR:py4j.java_gateway:An error occurred while trying to connect to the Java server (127.0.0.1:42185)\n",
      "Traceback (most recent call last):\n",
      "  File \"/home/hadoopuser/anaconda3/lib/python3.6/site-packages/py4j/java_gateway.py\", line 929, in _get_connection\n",
      "    connection = self.deque.pop()\n",
      "IndexError: pop from an empty deque\n",
      "\n",
      "During handling of the above exception, another exception occurred:\n",
      "\n",
      "Traceback (most recent call last):\n",
      "  File \"/home/hadoopuser/anaconda3/lib/python3.6/site-packages/py4j/java_gateway.py\", line 1067, in start\n",
      "    self.socket.connect((self.address, self.port))\n",
      "ConnectionRefusedError: [Errno 111] Connection refused\n",
      "ERROR:py4j.java_gateway:An error occurred while trying to connect to the Java server (127.0.0.1:42185)\n",
      "Traceback (most recent call last):\n",
      "  File \"/home/hadoopuser/anaconda3/lib/python3.6/site-packages/py4j/java_gateway.py\", line 929, in _get_connection\n",
      "    connection = self.deque.pop()\n",
      "IndexError: pop from an empty deque\n",
      "\n",
      "During handling of the above exception, another exception occurred:\n",
      "\n",
      "Traceback (most recent call last):\n",
      "  File \"/home/hadoopuser/anaconda3/lib/python3.6/site-packages/py4j/java_gateway.py\", line 1067, in start\n",
      "    self.socket.connect((self.address, self.port))\n",
      "ConnectionRefusedError: [Errno 111] Connection refused\n"
     ]
    },
    {
     "name": "stderr",
     "output_type": "stream",
     "text": [
      "ERROR:py4j.java_gateway:An error occurred while trying to connect to the Java server (127.0.0.1:42185)\n",
      "Traceback (most recent call last):\n",
      "  File \"/home/hadoopuser/anaconda3/lib/python3.6/site-packages/py4j/java_gateway.py\", line 929, in _get_connection\n",
      "    connection = self.deque.pop()\n",
      "IndexError: pop from an empty deque\n",
      "\n",
      "During handling of the above exception, another exception occurred:\n",
      "\n",
      "Traceback (most recent call last):\n",
      "  File \"/home/hadoopuser/anaconda3/lib/python3.6/site-packages/py4j/java_gateway.py\", line 1067, in start\n",
      "    self.socket.connect((self.address, self.port))\n",
      "ConnectionRefusedError: [Errno 111] Connection refused\n",
      "ERROR:py4j.java_gateway:An error occurred while trying to connect to the Java server (127.0.0.1:42185)\n",
      "Traceback (most recent call last):\n",
      "  File \"/home/hadoopuser/anaconda3/lib/python3.6/site-packages/py4j/java_gateway.py\", line 929, in _get_connection\n",
      "    connection = self.deque.pop()\n",
      "IndexError: pop from an empty deque\n",
      "\n",
      "During handling of the above exception, another exception occurred:\n",
      "\n",
      "Traceback (most recent call last):\n",
      "  File \"/home/hadoopuser/anaconda3/lib/python3.6/site-packages/py4j/java_gateway.py\", line 1067, in start\n",
      "    self.socket.connect((self.address, self.port))\n",
      "ConnectionRefusedError: [Errno 111] Connection refused\n",
      "ERROR:py4j.java_gateway:An error occurred while trying to connect to the Java server (127.0.0.1:42185)\n",
      "Traceback (most recent call last):\n",
      "  File \"/home/hadoopuser/anaconda3/lib/python3.6/site-packages/py4j/java_gateway.py\", line 929, in _get_connection\n",
      "    connection = self.deque.pop()\n",
      "IndexError: pop from an empty deque\n",
      "\n",
      "During handling of the above exception, another exception occurred:\n",
      "\n",
      "Traceback (most recent call last):\n",
      "  File \"/home/hadoopuser/anaconda3/lib/python3.6/site-packages/py4j/java_gateway.py\", line 1067, in start\n",
      "    self.socket.connect((self.address, self.port))\n",
      "ConnectionRefusedError: [Errno 111] Connection refused\n",
      "ERROR:py4j.java_gateway:An error occurred while trying to connect to the Java server (127.0.0.1:42185)\n",
      "Traceback (most recent call last):\n",
      "  File \"/home/hadoopuser/anaconda3/lib/python3.6/site-packages/py4j/java_gateway.py\", line 929, in _get_connection\n",
      "    connection = self.deque.pop()\n",
      "IndexError: pop from an empty deque\n",
      "\n",
      "During handling of the above exception, another exception occurred:\n",
      "\n",
      "Traceback (most recent call last):\n",
      "  File \"/home/hadoopuser/anaconda3/lib/python3.6/site-packages/py4j/java_gateway.py\", line 1067, in start\n",
      "    self.socket.connect((self.address, self.port))\n",
      "ConnectionRefusedError: [Errno 111] Connection refused\n",
      "ERROR:py4j.java_gateway:An error occurred while trying to connect to the Java server (127.0.0.1:42185)\n",
      "Traceback (most recent call last):\n",
      "  File \"/home/hadoopuser/anaconda3/lib/python3.6/site-packages/py4j/java_gateway.py\", line 929, in _get_connection\n",
      "    connection = self.deque.pop()\n",
      "IndexError: pop from an empty deque\n",
      "\n",
      "During handling of the above exception, another exception occurred:\n",
      "\n",
      "Traceback (most recent call last):\n",
      "  File \"/home/hadoopuser/anaconda3/lib/python3.6/site-packages/py4j/java_gateway.py\", line 1067, in start\n",
      "    self.socket.connect((self.address, self.port))\n",
      "ConnectionRefusedError: [Errno 111] Connection refused\n",
      "ERROR:py4j.java_gateway:An error occurred while trying to connect to the Java server (127.0.0.1:42185)\n",
      "Traceback (most recent call last):\n",
      "  File \"/home/hadoopuser/anaconda3/lib/python3.6/site-packages/py4j/java_gateway.py\", line 929, in _get_connection\n",
      "    connection = self.deque.pop()\n",
      "IndexError: pop from an empty deque\n",
      "\n",
      "During handling of the above exception, another exception occurred:\n",
      "\n",
      "Traceback (most recent call last):\n",
      "  File \"/home/hadoopuser/anaconda3/lib/python3.6/site-packages/py4j/java_gateway.py\", line 1067, in start\n",
      "    self.socket.connect((self.address, self.port))\n",
      "ConnectionRefusedError: [Errno 111] Connection refused\n",
      "ERROR:py4j.java_gateway:An error occurred while trying to connect to the Java server (127.0.0.1:42185)\n",
      "Traceback (most recent call last):\n",
      "  File \"/home/hadoopuser/anaconda3/lib/python3.6/site-packages/py4j/java_gateway.py\", line 929, in _get_connection\n",
      "    connection = self.deque.pop()\n",
      "IndexError: pop from an empty deque\n",
      "\n",
      "During handling of the above exception, another exception occurred:\n",
      "\n",
      "Traceback (most recent call last):\n",
      "  File \"/home/hadoopuser/anaconda3/lib/python3.6/site-packages/py4j/java_gateway.py\", line 1067, in start\n",
      "    self.socket.connect((self.address, self.port))\n",
      "ConnectionRefusedError: [Errno 111] Connection refused\n",
      "ERROR:py4j.java_gateway:An error occurred while trying to connect to the Java server (127.0.0.1:42185)\n",
      "Traceback (most recent call last):\n",
      "  File \"/home/hadoopuser/anaconda3/lib/python3.6/site-packages/py4j/java_gateway.py\", line 929, in _get_connection\n",
      "    connection = self.deque.pop()\n",
      "IndexError: pop from an empty deque\n",
      "\n",
      "During handling of the above exception, another exception occurred:\n",
      "\n",
      "Traceback (most recent call last):\n",
      "  File \"/home/hadoopuser/anaconda3/lib/python3.6/site-packages/py4j/java_gateway.py\", line 1067, in start\n",
      "    self.socket.connect((self.address, self.port))\n",
      "ConnectionRefusedError: [Errno 111] Connection refused\n",
      "ERROR:py4j.java_gateway:An error occurred while trying to connect to the Java server (127.0.0.1:42185)\n",
      "Traceback (most recent call last):\n",
      "  File \"/home/hadoopuser/anaconda3/lib/python3.6/site-packages/py4j/java_gateway.py\", line 929, in _get_connection\n",
      "    connection = self.deque.pop()\n",
      "IndexError: pop from an empty deque\n",
      "\n",
      "During handling of the above exception, another exception occurred:\n",
      "\n",
      "Traceback (most recent call last):\n",
      "  File \"/home/hadoopuser/anaconda3/lib/python3.6/site-packages/py4j/java_gateway.py\", line 1067, in start\n",
      "    self.socket.connect((self.address, self.port))\n",
      "ConnectionRefusedError: [Errno 111] Connection refused\n",
      "ERROR:py4j.java_gateway:An error occurred while trying to connect to the Java server (127.0.0.1:42185)\n",
      "Traceback (most recent call last):\n",
      "  File \"/home/hadoopuser/anaconda3/lib/python3.6/site-packages/py4j/java_gateway.py\", line 929, in _get_connection\n",
      "    connection = self.deque.pop()\n",
      "IndexError: pop from an empty deque\n",
      "\n",
      "During handling of the above exception, another exception occurred:\n",
      "\n",
      "Traceback (most recent call last):\n",
      "  File \"/home/hadoopuser/anaconda3/lib/python3.6/site-packages/py4j/java_gateway.py\", line 1067, in start\n",
      "    self.socket.connect((self.address, self.port))\n",
      "ConnectionRefusedError: [Errno 111] Connection refused\n",
      "ERROR:py4j.java_gateway:An error occurred while trying to connect to the Java server (127.0.0.1:42185)\n",
      "Traceback (most recent call last):\n",
      "  File \"/home/hadoopuser/anaconda3/lib/python3.6/site-packages/py4j/java_gateway.py\", line 929, in _get_connection\n",
      "    connection = self.deque.pop()\n",
      "IndexError: pop from an empty deque\n",
      "\n",
      "During handling of the above exception, another exception occurred:\n",
      "\n",
      "Traceback (most recent call last):\n",
      "  File \"/home/hadoopuser/anaconda3/lib/python3.6/site-packages/py4j/java_gateway.py\", line 1067, in start\n",
      "    self.socket.connect((self.address, self.port))\n",
      "ConnectionRefusedError: [Errno 111] Connection refused\n",
      "ERROR:py4j.java_gateway:An error occurred while trying to connect to the Java server (127.0.0.1:42185)\n",
      "Traceback (most recent call last):\n",
      "  File \"/home/hadoopuser/anaconda3/lib/python3.6/site-packages/py4j/java_gateway.py\", line 929, in _get_connection\n",
      "    connection = self.deque.pop()\n",
      "IndexError: pop from an empty deque\n",
      "\n",
      "During handling of the above exception, another exception occurred:\n",
      "\n",
      "Traceback (most recent call last):\n",
      "  File \"/home/hadoopuser/anaconda3/lib/python3.6/site-packages/py4j/java_gateway.py\", line 1067, in start\n",
      "    self.socket.connect((self.address, self.port))\n",
      "ConnectionRefusedError: [Errno 111] Connection refused\n",
      "ERROR:py4j.java_gateway:An error occurred while trying to connect to the Java server (127.0.0.1:42185)\n",
      "Traceback (most recent call last):\n",
      "  File \"/home/hadoopuser/anaconda3/lib/python3.6/site-packages/py4j/java_gateway.py\", line 929, in _get_connection\n",
      "    connection = self.deque.pop()\n",
      "IndexError: pop from an empty deque\n",
      "\n",
      "During handling of the above exception, another exception occurred:\n",
      "\n",
      "Traceback (most recent call last):\n",
      "  File \"/home/hadoopuser/anaconda3/lib/python3.6/site-packages/py4j/java_gateway.py\", line 1067, in start\n",
      "    self.socket.connect((self.address, self.port))\n",
      "ConnectionRefusedError: [Errno 111] Connection refused\n"
     ]
    }
   ],
   "source": [
    "df"
   ]
  },
  {
   "cell_type": "code",
   "execution_count": null,
   "metadata": {},
   "outputs": [],
   "source": []
  }
 ],
 "metadata": {
  "kernelspec": {
   "display_name": "Python 3",
   "language": "python",
   "name": "python3"
  },
  "language_info": {
   "codemirror_mode": {
    "name": "ipython",
    "version": 3
   },
   "file_extension": ".py",
   "mimetype": "text/x-python",
   "name": "python",
   "nbconvert_exporter": "python",
   "pygments_lexer": "ipython3",
   "version": "3.6.5"
  }
 },
 "nbformat": 4,
 "nbformat_minor": 2
}
